Workbook

Sheet H.EV
B3: PRE INVERSION | C3: INVERSION | E3: POST INVERSION
E4: 13 años
B5: Estudio a nivel de perfil | C5: Expediente tecnico | D5: Licitacion y contratacion de obra, ejecucion de obras, implementacion de equipos, elaboracion de programa de capacitacion, supersion y liquidacion | E5: Operación y mantenimiento
H6: ACTIVIDADES | I6: PERIODO 0 (Años) | K6: OPERACIÓN Y MANTENIMIENTO (13 Años)
I7: 2024 | J7: 2025 | K7: Año 1 | L7: Año 2 | M7: Año 3 | N7: Año 4 | O7: Año 5 | P7: Año 6 | Q7: Año 7 | R7: Año 8 | S7: Año 9 | T7: Año 10 | U7: Año 11 | V7: Año 12 | W7: Año 13
H9: FASE DE INVERSION
H10: Elaboracion de expediente tecnico
H11: Licitacion y contratacion de obra
H12: Construccion de la obra
H13: Salud y seguridad de obra
H14: Plan de contingencia
H15: Mitigacion ambiental
H16: Equipamiento
H17: Supervision
H18: Liquidacion de obra
H19: FASE DE POST INVERSION
H20: Operación y mantenimiento

Sheet CART.SERVICIOS
B3: CARTERA DE SERVICIOS | C3: ACTIVIDADES
B4: Consulta ambulatoria por medico general | C4: Consultorio de medicina general | D4: atencion
B5: Teleconsulta por medico general | C5: Teleconsultamedica | D5: atencion
B6: Atención ambulatoria por enfermera | C6: Consultorio CRED | D6: atencion
C7: Sala de estimulacion temprana
C8: Sala de Inmunizaciones | D8: vacuna
B9: Atencion ambulatoria por profesional de la salud | C9: Modulo para prevencion y consejeria de TBC
C10: Consejeria y prevencion de ITS, VIH y SIDA
C11: Atencíon integral y consejeria del Adolescente
C12: Atencíon integral del Adulto Mayor
C13: Consejería y prevención de Enf. No Transmisibles
B14: Atención ambulatoria por obstetra | C14: Control Prenatal + 1/2 S.H. | D14: atencion
C15: Planificacíon Familiar | D15: sesion
C16: Consejería y prevención del Cáncer
C17: Psicoprofilaxis
B18: Atención ambulatoria por cirujano dentista general con soporte de radiología oral | C18: Consultorio de odontologia general con soporte de radiografia | D18: atencion
B19: Atencion ambulatoria por psicologo | C19: Consultorio de psicologia
B20: Atencion ambbulatoria por personal de salud capacitado en salud mental | C20: Salud mental
B21: Atencion diferenciada de pacientes COVID u otras afecciones respiratorias | C21: COVID u otras afecciones respiratorias
B22: Atencion de urgencias y emergencias por medico general | C22: Topico Urgencias y emergencias | D22: atencion
B23: Atencion de ambienye de observacion de emergencia | C23: Sala de observacion de mergencia | D23: egreso
B24: Atencion patologia clinica | C24: Laboratorio | D24: muestra
B25: Atencion de radiologia y ecografia | C25: Ecografia | D25: examen
C26: Radiografia | D26: examen
B27: Atecncion con medicamentos | C27: Farmacia | D27: receta
B28: Desinfeccion y esterilizacion | C28: Desinfeccin y esterilizacion | D28: unidad esterilizada

Sheet Hoja1
B2: EE. SS | C2: GRUPOS DE EDAD
C3: 0 | D3: 1 | E3: 2 | F3: 3 | G3: 4 | H3: 5 | I3: 6 | J3: 7 | K3: 8 | L3: 9 | M3: 10 | N3: 11 | O3: 12 | P3: 13 | Q3: 14 | R3: 15 | S3: 16 | T3: 17 | U3: 18 | V3: 19 | W3: 20 - 24 | X3: 25 - 29 | Y3: 30 - 34 | Z3: 35 - 39 | AA3: 40 - 44 | AB3: 45 - 49 | AC3: 50- 54 | AD3: 55 - 59 | AE3: 60 - 64 | AF3: 65 - 69 | AG3: 70 - 74 | AH3: 75 - 79 | AI3: 80 y mas | AJ3: TOTAL
B4: P.S. Arhuay | C4: 7 | D4: 5 | E4: 13 | F4: 15 | G4: 13 | H4: 11 | I4: 7 | J4: 7 | K4: 7 | L4: 6 | M4: 5 | N4: 8 | O4: 7 | P4: 9 | Q4: 7 | R4: 5 | S4: 6 | T4: 5 | U4: 7 | V4: 6 | W4: 41 | X4: 47 | Y4: 40 | Z4: 32 | AA4: 34 | AB4: 29 | AC4: 25 | AD4: 23 | AE4: 23 | AF4: 16 | AG4: 13 | AH4: 9 | AI4: 19 | AJ4: =SUM(C4:AI4) -> 507
B8: POBLACION POR GRUPOS ESPECIALES P.S. ARHUAY | Z8: =+SUM(V4:AI4) -> 357
B9: EE.SS | C9: NIÑOS MENORES 5 AÑOS | E9: POBLACION FEMENINA | I9: GESTANTES | K9: NACIMIENTOS | M9: DIAS ESPECIALES
E10: Total | F10: 10-14 | G10: 15-19 | H10: 20-49 | M10: 28 dias | N10: 0-5 meses | O10: 6-11 meses
B11: P.S ARHUAY | C11: =+SUM(C4:G4) -> 53 | E11: 257 | F11: 17 | G11: 14 | H11: 115 | I11: 18 | K11: 7 | M11: 3 | N11: 3 | O11: 3
B14: POBLACION PROYECTADA P.S HUANCHAY
B16: Año base (2024) | D16: 507
B17: Tasa de crecimiento* | D17: =+Hoja3!C8 -> 0.0003
B18: *INEI -
B20: AÑO | C20: POBLACION
B21: 2024 | C21: =+D16 -> 507
B22: =+B21+1 -> 2025 | C22: =ROUND(($C$21*(1+$D$17)^1),0) -> 507 | L22: =21/12 -> 1.75
B23: =+B22+1 -> 2026 | C23: =ROUND(($C$21*(1+$D$17)^2),0) -> 507
B24: =+B23+1 -> 2027 | C24: =ROUND(($C$21*(1+$D$17)^3),0) -> 507
B25: =+B24+1 -> 2028 | C25: =ROUND(($C$21*(1+$D$17)^4),0) -> 508
B26: =+B25+1 -> 2029 | C26: =ROUND(($C$21*(1+$D$17)^5),0) -> 508
B27: =+B26+1 -> 2030 | C27: =ROUND(($C$21*(1+$D$17)^6),0) -> 508
B28: =+B27+1 -> 2031 | C28: =ROUND(($C$21*(1+$D$17)^7),0) -> 508
B29: =+B28+1 -> 2032 | C29: =ROUND(($C$21*(1+$D$17)^8),0) -> 508
B30: =+B29+1 -> 2033 | C30: =ROUND(($C$21*(1+$D$17)^9),0) -> 508
B31: =+B30+1 -> 2034 | C31: =ROUND(($C$21*(1+$D$17)^10),0) -> 509
B32: =+B31+1 -> 2035 | C32: =ROUND(($C$21*(1+$D$17)^11),0) -> 509
B33: =+B32+1 -> 2036 | C33: =ROUND(($C$21*(1+$D$17)^12),0) -> 509
B34: TOTAL | C34: =SUM(C22:C33) -> 6096

Sheet Hoja3
B2: TOTAL DE LA POBLACION
B3: POBLACION DEL DISTRITO DE RAHUAPAMPA
B4: CENSO | C4: TOTAL
B5: 2017 | C5: 741
B6: 2007 | C6: 739
B7: TASA DE CRECIMIENTO DE LA POBLACION TOTAL | C7: =+(((C6/C5)^(1/(B6-B5)))-1)*100 -> 0.027030696
C8: =ROUND((C7/100),4) -> 0.0003
B11: POBLACION DE LA PROVINCIA DE HUARI
B12: CENSO | C12: POBLACION
B13: 2017 | C13: 62278
B14: 2007 | C14: 62598
B15: TASA DE CRECIMIENTO | C15: =+(((C14/C13)^(1/(B14-B13)))-1)*100 -> -0.051237822
C16: =ROUND((C15/100),4) -> -0.0005
B18: POBLACION DEL DEPARTAMENTO DE ANCASH
B19: CENSO | C19: POBLACION
B20: 2017 | C20: 1083519
B21: 2007 | C21: 1063459
B22: TASA DE CRECIMIENTO | C22: =+(((C21/C20)^(1/(B21-B20)))-1)*100 -> 0.18704746
C23: =ROUND((C22/100),4) -> 0.0019

Sheet POBLACION DE REFERENCIA
B1: POBLACION DE REFERENCIA
B2: Poblacion de referencia: Consultorio de medicina general (Numero de personas de 0 a 85 años a mas) en el año 2024 | C2: 507 x 100% = | D2: 507
B3: Poblacion de referencia: Teleconsultamedica (Numero de personas de 0 a 85 años a mas) en el año 2024 | C3: 507 x 100% = | D3: 507
B4: Poblacion de referencia: Consultorio CRED (Numero de niños menores de 11 años)en el año 2024 | C4: 107 x 100% = | D4: 107
B5: Poblacion de referencia: Estimulacion temprana (Numero de niños menores de 3 años) en el año 2024 | C5: 43 x 100 % = | D5: 43
B6: Poblacion de referencia: Inmunizaciones (Menores de 4 años, gestantes) en el año 2024 | C6: 71 x 100% = | D6: 71
B7: Poblacion de referencia: Prevencion y consejeria de TBC (Mayores a 18 a 85 años a mas) en el año 2024 | C7: 364 * 100% = | D7: 364
B8: Poblacion de referencia: Consejeria y prevencion de ITS, VIH y SIDA (mayores a 18 años) en el año 2024 | C8: 364 * 100% = | D8: 364
B9: Poblacion de referencia: Atencíon integral y consejeria del Adolescente en el año 2024 | C9: 39 * 100% = | D9: 39
B10: Poblacion de referencia: Atencíon integral del Adulto Mayor en el año 2024 | C10: 364 x 100% = | D10: 364
B11: Poblacion de referencia: Consejería y prevención de Enf. No Transmisibles (mayores a 18 años) en el año 2024 | C11: 364 x 100% = | D11: 364
B12: Poblacion de referencia: Control Prenatal + 1/2 S.H (gestantes) en el año 2024 | C12: 18 x 100% = | D12: 18
B13: Poblacion de referencia: Planificacíon Familiar (MEF DE 15 a 49 años) en el año 2024 | C13: 252 x 100% = | D13: 252
... B24: Poblacion de referencia: Desinfeccion y esterilizacion (0 a 85 años a mas) en el año 2024 | C24: 507 x 100% = | D24: 507
B28: POBLACION SUJETO DE INTERVENCION (PERSONAS EN SUS DIFERENTES ETAPAS DE VIDA) | C28: PERIODO DE INVERSION | F28: PERIODO DE POST INVERSION
C29: 0 | F29: 1 | G29: 2 | H29: 3 | I29: 4 | J29: 5 | K29: 6 | L29: 7 | M29: 8 | N29: 9 | O29: 10
C30: 2024 | D30: 2025 | E30: 2026 | F30: 2027 | G30: 2028 | H30: 2029 | I30: 2030 | J30: 2031 | K30: 2032 | L30: 2033 | M30: 2034 | N30: 2035 | O30: 2036
B31: Medicina General | C31: =+C32 -> 507 | D31: =+D32 -> 507 | E31: =+E32 -> 507 | F31: =+F32 -> 507 | G31: =+G32 -> 508 | H31: =+H32 -> 508 | I31: =+I32 -> 508 | J31: =+J32 -> 508 | ... O31: =+O32 -> 509
B32: Medicina General (0 a 85 años a mas) | C32: =+Hoja1!AJ4 -> 507 | D32: =ROUND(($C$32*(1+$A$73)^(D30-$C$30)),0) -> 507 | E32: =ROUND(($C$32*(1+$A$73)^(E30-$C$30)),0) -> 507 | F32: =ROUND(($C$32*(1+$A$73)^(F30-$C$30)),0) -> 507 | G32: =ROUND(($C$32*(1+$A$73)^(G30-$C$30)),0) -> 508 | H32: =ROUND(($C$32*(1+$A$73)^(H30-$C$30)),0) -> 508 | I32: =ROUND(($C$32*(1+$A$73)^(I30-$C$30)),0) -> 508 | J32: =ROUND(($C$32*(1+$A$73)^(J30-$C$30)),0) -> 508 | K32: =ROUND(($C$32*(1+$A$73)^(K30-$C$30)),0) -> 508 | ... O32: =ROUND(($C$32*(1+$A$73)^(O30-$C$30)),0) -> 509
B34: POBLACION SUJETO DE INTERVENCION (PERSONAS EN SUS DIFERENTES ETAPAS DE VIDA) | C34: PERIODO DE INVERSION | F34: PERIODO DE POST INVERSION
C35: 0 | F35: 1 | G35: 2 | H35: 3 | I35: 4 | J35: 5 | K35: 6 | L35: 7 | M35: 8 | N35: 9 | O35: 10
C36: 2024 | D36: 2025 | E36: 2026 | F36: 2027 | G36: 2028 | H36: 2029 | I36: 2030 | J36: 2031 | K36: 2032 | L36: 2033 | M36: 2034 | N36: 2035 | O36: 2036
B37: Teleconsulta medica | C37: =+C38 -> 507 | D37: =+D38 -> 507 | E37: =+E38 -> 507 | F37: =+F38 -> 507 | G37: =+G38 -> 508 | H37: =+H38 -> 508 | I37: =+I38 -> 508 | J37: =+J38 -> 508 | ... O37: =+O38 -> 509
B38: Medicina General (0 a 85 años a mas) | C38: =+Hoja1!AJ4 -> 507 | D38: =ROUND(($C$38*(1+$A$73)^(D36-$C$36)),0) -> 507 | E38: =ROUND(($C$38*(1+$A$73)^(E36-$C$36)),0) -> 507 | F38: =ROUND(($C$38*(1+$A$73)^(F36-$C$36)),0) -> 507 | G38: =ROUND(($C$38*(1+$A$73)^(G36-$C$36)),0) -> 508 | H38: =ROUND(($C$38*(1+$A$73)^(H36-$C$36)),0) -> 508 | I38: =ROUND(($C$38*(1+$A$73)^(I36-$C$36)),0) -> 508 | J38: =ROUND(($C$38*(1+$A$73)^(J36-$C$36)),0) -> 508 | K38: =ROUND(($C$38*(1+$A$73)^(K36-$C$36)),0) -> 508 | ... O38: =ROUND(($C$38*(1+$A$73)^(O36-$C$36)),0) -> 509
B40: POBLACION SUJETO DE INTERVENCION | C40: PERIODO DE INVERSION | F40: PERIODO DE POST INVERSION
C41: 0 | F41: 1 | G41: 2 | H41: 3 | I41: 4 | J41: 5 | K41: 6 | L41: 7 | M41: 8 | N41: 9 | O41: 10
C42: =+C36 -> 2024 | D42: =+D36 -> 2025 | E42: =+E36 -> 2026 | F42: =+F36 -> 2027 | G42: =+G36 -> 2028 | H42: =+H36 -> 2029 | I42: =+I36 -> 2030 | J42: =+J36 -> 2031 | ... O42: =+O36 -> 2036
B43: CRED (< de 11 años) | C43: =+SUM(C44:C50) -> 107 | D43: =+SUM(D44:D50) -> 107 | E43: =+SUM(E44:E50) -> 107 | F43: =+SUM(F44:F50) -> 107 | G43: =+SUM(G44:G50) -> 107 | H43: =+SUM(H44:H50) -> 107 | I43: =+SUM(I44:I50) -> 107 | J43: =+SUM(J44:J50) -> 107 | ... O43: =+SUM(O44:O50) -> 107
B44: < de 29 dias | C44: =+Hoja1!M11 -> 3 | D44: =ROUND(($C$44*(1+$A$73)^(D42-$C$42)),0) -> 3 | E44: =ROUND(($C$44*(1+$A$73)^(E42-$C$42)),0) -> 3 | F44: =ROUND(($C$44*(1+$A$73)^(F42-$C$42)),0) -> 3 | G44: =ROUND(($C$44*(1+$A$73)^(G42-$C$42)),0) -> 3 | H44: =ROUND(($C$44*(1+$A$73)^(H42-$C$42)),0) -> 3 | I44: =ROUND(($C$44*(1+$A$73)^(I42-$C$42)),0) -> 3 | J44: =ROUND(($C$44*(1+$A$73)^(J42-$C$42)),0) -> 3 | K44: =ROUND(($C$44*(1+$A$73)^(K42-$C$42)),0) -> 3 | ... O44: =ROUND(($C$44*(1+$A$73)^(O42-$C$42)),0) -> 3
B45: < de 1 año | C45: =+Hoja1!C4 -> 7 | D45: =ROUND(($C$45*(1+$A$73)^(D42-$C$42)),0) -> 7 | E45: =ROUND(($C$45*(1+$A$73)^(E42-$C$42)),0) -> 7 | F45: =ROUND(($C$45*(1+$A$73)^(F42-$C$42)),0) -> 7 | G45: =ROUND(($C$45*(1+$A$73)^(G42-$C$42)),0) -> 7 | H45: =ROUND(($C$45*(1+$A$73)^(H42-$C$42)),0) -> 7 | I45: =ROUND(($C$45*(1+$A$73)^(I42-$C$42)),0) -> 7 | J45: =ROUND(($C$45*(1+$A$73)^(J42-$C$42)),0) -> 7 | K45: =ROUND(($C$45*(1+$A$73)^(K42-$C$42)),0) -> 7 | ... O45: =ROUND(($C$45*(1+$A$73)^(O42-$C$42)),0) -> 7
B46: 1 año | C46: =+Hoja1!D4 -> 5 | D46: =ROUND(($C$46*(1+$A$73)^(D42-$C$42)),0) -> 5 | E46: =ROUND(($C$46*(1+$A$73)^(E42-$C$42)),0) -> 5 | F46: =ROUND(($C$46*(1+$A$73)^(F42-$C$42)),0) -> 5 | G46: =ROUND(($C$46*(1+$A$73)^(G42-$C$42)),0) -> 5 | H46: =ROUND(($C$46*(1+$A$73)^(H42-$C$42)),0) -> 5 | I46: =ROUND(($C$46*(1+$A$73)^(I42-$C$42)),0) -> 5 | J46: =ROUND(($C$46*(1+$A$73)^(J42-$C$42)),0) -> 5 | K46: =ROUND(($C$46*(1+$A$73)^(K42-$C$42)),0) -> 5 | ... O46: =ROUND(($C$46*(1+$A$73)^(O42-$C$42)),0) -> 5
B47: 2 años | C47: =+Hoja1!E4 -> 13 | D47: =ROUND(($C$47*(1+$A$73)^(D42-$C$42)),0) -> 13 | E47: =ROUND(($C$47*(1+$A$73)^(E42-$C$42)),0) -> 13 | F47: =ROUND(($C$47*(1+$A$73)^(F42-$C$42)),0) -> 13 | G47: =ROUND(($C$47*(1+$A$73)^(G42-$C$42)),0) -> 13 | H47: =ROUND(($C$47*(1+$A$73)^(H42-$C$42)),0) -> 13 | I47: =ROUND(($C$47*(1+$A$73)^(I42-$C$42)),0) -> 13 | J47: =ROUND(($C$47*(1+$A$73)^(J42-$C$42)),0) -> 13 | K47: =ROUND(($C$47*(1+$A$73)^(K42-$C$42)),0) -> 13 | ... O47: =ROUND(($C$47*(1+$A$73)^(O42-$C$42)),0) -> 13
B48: 3 años | C48: =+Hoja1!F4 -> 15 | D48: =ROUND(($C$48*(1+$A$73)^(D42-$C$42)),0) -> 15 | E48: =ROUND(($C$48*(1+$A$73)^(E42-$C$42)),0) -> 15 | F48: =ROUND(($C$48*(1+$A$73)^(F42-$C$42)),0) -> 15 | G48: =ROUND(($C$48*(1+$A$73)^(G42-$C$42)),0) -> 15 | H48: =ROUND(($C$48*(1+$A$73)^(H42-$C$42)),0) -> 15 | I48: =ROUND(($C$48*(1+$A$73)^(I42-$C$42)),0) -> 15 | J48: =ROUND(($C$48*(1+$A$73)^(J42-$C$42)),0) -> 15 | K48: =ROUND(($C$48*(1+$A$73)^(K42-$C$42)),0) -> 15 | ... O48: =ROUND(($C$48*(1+$A$73)^(O42-$C$42)),0) -> 15
B49: 4 años | C49: =+Hoja1!G4 -> 13 | D49: =ROUND(($C$49*(1+$A$73)^(D42-$C$42)),0) -> 13 | E49: =ROUND(($C$49*(1+$A$73)^(E42-$C$42)),0) -> 13 | F49: =ROUND(($C$49*(1+$A$73)^(F42-$C$42)),0) -> 13 | G49: =ROUND(($C$49*(1+$A$73)^(G42-$C$42)),0) -> 13 | H49: =ROUND(($C$49*(1+$A$73)^(H42-$C$42)),0) -> 13 | I49: =ROUND(($C$49*(1+$A$73)^(I42-$C$42)),0) -> 13 | J49: =ROUND(($C$49*(1+$A$73)^(J42-$C$42)),0) -> 13 | K49: =ROUND(($C$49*(1+$A$73)^(K42-$C$42)),0) -> 13 | ... O49: =ROUND(($C$49*(1+$A$73)^(O42-$C$42)),0) -> 13
B50: 5 a 11 años | C50: =+SUM(Hoja1!H4:N4) -> 51 | D50: =ROUND(($C$50*(1+$A$73)^(D42-$C$42)),0) -> 51 | E50: =ROUND(($C$50*(1+$A$73)^(E42-$C$42)),0) -> 51 | F50: =ROUND(($C$50*(1+$A$73)^(F42-$C$42)),0) -> 51 | G50: =ROUND(($C$50*(1+$A$73)^(G42-$C$42)),0) -> 51 | H50: =ROUND(($C$50*(1+$A$73)^(H42-$C$42)),0) -> 51 | I50: =ROUND(($C$50*(1+$A$73)^(I42-$C$42)),0) -> 51 | J50: =ROUND(($C$50*(1+$A$73)^(J42-$C$42)),0) -> 51 | K50: =ROUND(($C$50*(1+$A$73)^(K42-$C$42)),0) -> 51 | ... O50: =ROUND(($C$50*(1+$A$73)^(O42-$C$42)),0) -> 51
B52: POBLACION SUJETO DE INTERVENCION | C52: PERIODO DE INVERSION | F52: PERIODO DE POST INVERSION
C53: 0 | F53: 1 | G53: 2 | H53: 3 | I53: 4 | J53: 5 | K53: 6 | L53: 7 | M53: 8 | N53: 9 | O53: 10
C54: =+C42 -> 2024 | D54: =+D42 -> 2025 | E54: =+E42 -> 2026 | F54: =+F42 -> 2027 | G54: =+G42 -> 2028 | H54: =+H42 -> 2029 | I54: =+I42 -> 2030 | J54: =+J42 -> 2031 | ... O54: =+O42 -> 2036
B55: ESTIMULACION TEMPRANA (< de 3 años) | C55: =+SUM(C56:C60) -> 43 | D55: =+SUM(D56:D60) -> 43 | E55: =+SUM(E56:E60) -> 43 | F55: =+SUM(F56:F60) -> 43 | G55: =+SUM(G56:G60) -> 43 | H55: =+SUM(H56:H60) -> 43 | I55: =+SUM(I56:I60) -> 43 | J55: =+SUM(J56:J60) -> 43 | ... O55: =+SUM(O56:O60) -> 43
B56: < 29 dias | C56: =+Hoja1!M11 -> 3 | D56: =+ROUND(($C$56*(1+$A$73)^(D54-$C$54)),0) -> 3 | E56: =+ROUND(($C$56*(1+$A$73)^(E54-$C$54)),0) -> 3 | F56: =+ROUND(($C$56*(1+$A$73)^(F54-$C$54)),0) -> 3 | G56: =+ROUND(($C$56*(1+$A$73)^(G54-$C$54)),0) -> 3 | H56: =+ROUND(($C$56*(1+$A$73)^(H54-$C$54)),0) -> 3 | I56: =+ROUND(($C$56*(1+$A$73)^(I54-$C$54)),0) -> 3 | J56: =+ROUND(($C$56*(1+$A$73)^(J54-$C$54)),0) -> 3 | K56: =+ROUND(($C$56*(1+$A$73)^(K54-$C$54)),0) -> 3 | ... O56: =+ROUND(($C$56*(1+$A$73)^(O54-$C$54)),0) -> 3
...

Sheet POBLACION DEMANDANTE POTENCIAL
C1: POBLACION DE REFERENCIA
C2: Poblacion de referencia: Consultorio de medicina general (Numero de personas de 0 a 85 años a mas) en el año 2024 | D2: 507 x 48 % = | E2: =507*48% -> 243.36
C3: Poblacion demandante potencial: Teleconsultamedica (Numero de personas de 0 a 85 años a mas) en el año 2024 | D3: 507 x 48% = | E3: =507*48% -> 243.36
C4: Poblacion demandante potencial: Consultorio CRED (Numero de niños menores de 11 años)en el año 2024 | D4: 107 x 100% = | E4: 107
C5: Poblacion demandante potencial: Estimulacion temprana (Numero de niños menores de 3 años) en el año 2024 | D5: 43 x 100 % = | E5: 43
C6: Poblacion demandante potencial: Inmunizaciones (Menores de 4 años, gestantes) en el año 2024 | D6: 71 x 100% = | E6: 71
C7: Poblacion demandante potencial: Prevencion y consejeria de TBC (Mayores a 18 a 85 años a mas) en el año 2024 | D7: 364 * 100% = | E7: 364
C8: Poblacion demandante potencial: Consejeria y prevencion de ITS, VIH y SIDA (mayores a 18 años) en el año 2024 | D8: 364 * 100% = | E8: 364
C9: Poblacion demandante potencial: Atencíon integral y consejeria del Adolescente en el año 2024 | D9: 39 * 100% = | E9: 39
C10: Poblacion demandante potencial: Atencíon integral del Adulto Mayor en el año 2024 | D10: 364 x 100% = | E10: 364
C11: Poblacion demandante potencial: Consejería y prevención de Enf. No Transmisibles (mayores a 18 años) en el año 2024 | D11: 364 x 100% = | E11: 364
C12: Poblacion demandante potencial: Control Prenatal + 1/2 S.H (gestantes) en el año 2024 | D12: 18 x 100% = | E12: 18
C13: Poblacion demandante potencial: Planificacíon Familiar (MEF DE 15 a 49 años) en el año 2024 | D13: 252 x 100% = | E13: 252
C14: Poblacion demandante potencial: Consejería y prevención del Cáncer (mayores a 18 años) en el año 2024 | D14: 364 x 100% = | E14: 364
C15: Poblacion demandante potencial: Psicoprofilaxis (gestantes) en el año 2024 | D15: 18 x 100% = | E15: 18
C16: Poblacion demandante potencial: Consultorio de odontologia general con soporte de radiografia (4 a 85 años a mas) en el año 2024 | D16: 467 x 48% = | E16: =467*48% -> 224.16
C17: Poblacion demandante potencial: Consultorio de psicologia (de 3 a 85 años a mas) en el año 2024 | D17: 482 x 100% | E17: 482
C18: Poblacion demandante potencial: Urgencias y emergencias (de 0 a 85 años a mas) en el año 2024 | D18: 507 x 48% = | E18: =507*48% -> 243.36
C19: Poblacion demandante potencial: Sala de observacion de emergencia (de 0 a 85 años a mas) en el año 2024 | D19: 507 x 48% = | E19: =507*48% -> 243.36
C20: Poblacion demandante potencial: Laboratorio (0 a 85 años a mas) en el año 2024 | D20: 507 x 48% = | E20: =507*48% -> 243.36
C21: Poblacion demandante potencial: Ecografia (0 a 85 años a mas) en el año 2024 | D21: 507 x 48% = | E21: =507*48% -> 243.36
C22: Poblacion demandante potencial: Radiografia (0 a 85 años a mas) en el año 2024 | D22: 507 x 48% = | E22: =507*48% -> 243.36
C23: Poblacion demandante potencial: Farmacia (0 a 85 años a mas) en el año 2024 | D23: 507 x 48% = | E23: =507*48% -> 243.36
C24: Poblacion demandante potencial: Desinfeccion y esterilizacion (0 a 85 años a mas) en el año 2024 | D24: 507 x 100% = | E24: 507
C28: POBLACION SUJETO DE INTERVENCION (PERSONAS EN SUS DIFERENTES ETAPAS DE VIDA) | D28: PERIODO DE INVERSION | G28: PERIODO DE POST INVERSION
D29: 0 | G29: 1 | H29: 2 | I29: 3 | J29: 4 | K29: 5 | L29: 6 | M29: 7 | N29: 8 | O29: 9 | P29: 10
D30: 2024 | E30: 2025 | F30: 2026 | G30: 2027 | H30: 2028 | I30: 2029 | J30: 2030 | K30: 2031 | L30: 2032 | M30: 2033 | N30: 2034 | O30: 2035 | P30: 2036
C31: Medicina General | D31: =+'POBLACION DE REFERENCIA'!C31 -> 507 | E31: =+'POBLACION DE REFERENCIA'!D31 -> 507 | F31: =+'POBLACION DE REFERENCIA'!E31 -> 507 | G31: =+'POBLACION DE REFERENCIA'!F31 -> 507 | H31: =+'POBLACION DE REFERENCIA'!G31 -> 508 | I31: =+'POBLACION DE REFERENCIA'!H31 -> 508 | J31: =+'POBLACION DE REFERENCIA'!I31 -> 508 | K31: =+'POBLACION DE REFERENCIA'!J31 -> 508 | ... P31: =+'POBLACION DE REFERENCIA'!O31 -> 509
C32: 0 a 85 años a mas | D32: =+'POBLACION DE REFERENCIA'!C32*48% -> 243.36 | E32: =ROUND(($D$32*(1+$A$73)^(E30-$D$30)),0) -> 243 | F32: =ROUND(($D$32*(1+$A$73)^(F30-$D$30)),0) -> 244 | G32: =ROUND(($D$32*(1+$A$73)^(G30-$D$30)),0) -> 244 | H32: =ROUND(($D$32*(1+$A$73)^(H30-$D$30)),0) -> 244 | I32: =ROUND(($D$32*(1+$A$73)^(I30-$D$30)),0) -> 244 | J32: =ROUND(($D$32*(1+$A$73)^(J30-$D$30)),0) -> 244 | K32: =ROUND(($D$32*(1+$A$73)^(K30-$D$30)),0) -> 244 | L32: =ROUND(($D$32*(1+$A$73)^(L30-$D$30)),0) -> 244 | ... P32: =ROUND(($D$32*(1+$A$73)^(P30-$D$30)),0) -> 244
C34: POBLACION SUJETO DE INTERVENCION (PERSONAS EN SUS DIFERENTES ETAPAS DE VIDA) | D34: PERIODO DE INVERSION | G34: PERIODO DE POST INVERSION
D35: 0 | G35: 1 | H35: 2 | I35: 3 | J35: 4 | K35: 5 | L35: 6 | M35: 7 | N35: 8 | O35: 9 | P35: 10
D36: 2024 | E36: 2025 | F36: 2026 | G36: 2027 | H36: 2028 | I36: 2029 | J36: 2030 | K36: 2031 | L36: 2032 | M36: 2033 | N36: 2034 | O36: 2035 | P36: 2036
C37: Teleconsulta medica | D37: =+D38 -> 243.36 | E37: =+E38 -> 243 | F37: =+F38 -> 244 | G37: =+G38 -> 244 | H37: =+H38 -> 244 | I37: =+I38 -> 244 | J37: =+J38 -> 244 | K37: =+K38 -> 244 | ... P37: =+P38 -> 244
C38: 0 a 85 años a mas | D38: =+'POBLACION DE REFERENCIA'!C38*48% -> 243.36 | E38: =ROUND(($D$38*(1+$A$73)^(E36-$D$36)),0) -> 243 | F38: =ROUND(($D$38*(1+$A$73)^(F36-$D$36)),0) -> 244 | G38: =ROUND(($D$38*(1+$A$73)^(G36-$D$36)),0) -> 244 | H38: =ROUND(($D$38*(1+$A$73)^(H36-$D$36)),0) -> 244 | I38: =ROUND(($D$38*(1+$A$73)^(I36-$D$36)),0) -> 244 | J38: =ROUND(($D$38*(1+$A$73)^(J36-$D$36)),0) -> 244 | K38: =ROUND(($D$38*(1+$A$73)^(K36-$D$36)),0) -> 244 | L38: =ROUND(($D$38*(1+$A$73)^(L36-$D$36)),0) -> 244 | ... P38: =ROUND(($D$38*(1+$A$73)^(P36-$D$36)),0) -> 244
C40: POBLACION SUJETO DE INTERVENCION | D40: PERIODO DE INVERSION | G40: PERIODO DE POST INVERSION
D41: 0 | G41: 1 | H41: 2 | I41: 3 | J41: 4 | K41: 5 | L41: 6 | M41: 7 | N41: 8 | O41: 9 | P41: 10
D42: =+D36 -> 2024 | E42: =+E36 -> 2025 | F42: =+F36 -> 2026 | G42: =+G36 -> 2027 | H42: =+H36 -> 2028 | I42: =+I36 -> 2029 | J42: =+J36 -> 2030 | K42: =+K36 -> 2031 | ... P42: =+P36 -> 2036
C43: CRED (< de 11 años) | D43: =+SUM(D44:D50) -> 107 | E43: =+SUM(E44:E50) -> 107 | F43: =+SUM(F44:F50) -> 107 | G43: =+SUM(G44:G50) -> 107 | H43: =+SUM(H44:H50) -> 107 | I43: =+SUM(I44:I50) -> 107 | J43: =+SUM(J44:J50) -> 107 | K43: =+SUM(K44:K50) -> 107 | ... P43: =+SUM(P44:P50) -> 107
C44: < de 29 dias | D44: =+'POBLACION DE REFERENCIA'!C44 -> 3 | E44: =+'POBLACION DE REFERENCIA'!D44 -> 3 | F44: =+'POBLACION DE REFERENCIA'!E44 -> 3 | G44: =+'POBLACION DE REFERENCIA'!F44 -> 3 | H44: =+'POBLACION DE REFERENCIA'!G44 -> 3 | I44: =+'POBLACION DE REFERENCIA'!H44 -> 3 | J44: =+'POBLACION DE REFERENCIA'!I44 -> 3 | K44: =+'POBLACION DE REFERENCIA'!J44 -> 3 | ... P44: =+'POBLACION DE REFERENCIA'!O44 -> 3
C45: < de 1 año | D45: =+'POBLACION DE REFERENCIA'!C45 -> 7 | E45: =+'POBLACION DE REFERENCIA'!D45 -> 7 | F45: =+'POBLACION DE REFERENCIA'!E45 -> 7 | G45: =+'POBLACION DE REFERENCIA'!F45 -> 7 | H45: =+'POBLACION DE REFERENCIA'!G45 -> 7 | I45: =+'POBLACION DE REFERENCIA'!H45 -> 7 | J45: =+'POBLACION DE REFERENCIA'!I45 -> 7 | K45: =+'POBLACION DE REFERENCIA'!J45 -> 7 | ... P45: =+'POBLACION DE REFERENCIA'!O45 -> 7
...

Sheet POBLACION DEMANDANTE EFECTIVA
C5: POBLACION SUJETO DE INTERVENCION (PERSONAS EN SUS DIFERENTES ETAPAS DE VIDA) | D5: PERIODO DE INVERSION | G5: PERIODO DE POST INVERSION
D6: 0 | G6: 1 | H6: 2 | I6: 3 | J6: 4 | K6: 5 | L6: 6 | M6: 7 | N6: 8 | O6: 9 | P6: 10
A7: =+Hoja1!D17 -> 0.0003 | D7: 2024 | E7: 2025 | F7: 2026 | G7: 2027 | H7: 2028 | I7: 2029 | J7: 2030 | K7: 2031 | L7: 2032 | M7: 2033 | N7: 2034 | O7: 2035 | P7: 2036
C8: Medicina General | D8: =+D9 -> 170.352 | E8: =+E9 -> 170 | F8: =+F9 -> 170 | G8: =+G9 -> 171 | H8: =+H9 -> 171 | I8: =+I9 -> 171 | J8: =+J9 -> 171 | K8: =+K9 -> 171 | ... P8: =+P9 -> 171
C9: 0 a 85 años a mas | D9: =+'POBLACION DEMANDANTE POTENCIAL'!D32*70% -> 170.352 | E9: =ROUND(($D$9*(1+$A$7)^(E7-$D$7)),0) -> 170 | F9: =ROUND(($D$9*(1+$A$7)^(F7-$D$7)),0) -> 170 | G9: =ROUND(($D$9*(1+$A$7)^(G7-$D$7)),0) -> 171 | H9: =ROUND(($D$9*(1+$A$7)^(H7-$D$7)),0) -> 171 | I9: =ROUND(($D$9*(1+$A$7)^(I7-$D$7)),0) -> 171 | J9: =ROUND(($D$9*(1+$A$7)^(J7-$D$7)),0) -> 171 | K9: =ROUND(($D$9*(1+$A$7)^(K7-$D$7)),0) -> 171 | L9: =ROUND(($D$9*(1+$A$7)^(L7-$D$7)),0) -> 171 | ... P9: =ROUND(($D$9*(1+$A$7)^(P7-$D$7)),0) -> 171
C11: POBLACION SUJETO DE INTERVENCION (PERSONAS EN SUS DIFERENTES ETAPAS DE VIDA) | D11: PERIODO DE INVERSION | G11: PERIODO DE POST INVERSION
D12: 0 | G12: 1 | H12: 2 | I12: 3 | J12: 4 | K12: 5 | L12: 6 | M12: 7 | N12: 8 | O12: 9 | P12: 10
D13: 2024 | E13: 2025 | F13: 2026 | G13: 2027 | H13: 2028 | I13: 2029 | J13: 2030 | K13: 2031 | L13: 2032 | M13: 2033 | N13: 2034 | O13: 2035 | P13: 2036
C14: Teleconsulta medica | D14: =+D15 -> 170.352 | E14: =+E15 -> 170 | F14: =+F15 -> 170 | G14: =+G15 -> 171 | H14: =+H15 -> 171 | I14: =+I15 -> 171 | J14: =+J15 -> 171 | K14: =+K15 -> 171 | ... P14: =+P15 -> 171
C15: 0 a 85 años a mas | D15: =+'POBLACION DEMANDANTE POTENCIAL'!D38*70% -> 170.352 | E15: =ROUND(($D$15*(1+$A$7)^(E13-$D$13)),0) -> 170 | F15: =ROUND(($D$15*(1+$A$7)^(F13-$D$13)),0) -> 170 | G15: =ROUND(($D$15*(1+$A$7)^(G13-$D$13)),0) -> 171 | H15: =ROUND(($D$15*(1+$A$7)^(H13-$D$13)),0) -> 171 | I15: =ROUND(($D$15*(1+$A$7)^(I13-$D$13)),0) -> 171 | J15: =ROUND(($D$15*(1+$A$7)^(J13-$D$13)),0) -> 171 | K15: =ROUND(($D$15*(1+$A$7)^(K13-$D$13)),0) -> 171 | L15: =ROUND(($D$15*(1+$A$7)^(L13-$D$13)),0) -> 171 | ... P15: =ROUND(($D$15*(1+$A$7)^(P13-$D$13)),0) -> 171
C17: POBLACION SUJETO DE INTERVENCION | D17: PERIODO DE INVERSION | G17: PERIODO DE POST INVERSION
D18: 0 | G18: 1 | H18: 2 | I18: 3 | J18: 4 | K18: 5 | L18: 6 | M18: 7 | N18: 8 | O18: 9 | P18: 10
D19: =+D13 -> 2024 | E19: =+E13 -> 2025 | F19: =+F13 -> 2026 | G19: =+G13 -> 2027 | H19: =+H13 -> 2028 | I19: =+I13 -> 2029 | J19: =+J13 -> 2030 | K19: =+K13 -> 2031 | ... P19: =+P13 -> 2036
C20: CRED (< de 11 años) | D20: =+SUM(D21:D27) -> 85.6 | E20: =+SUM(E21:E27) -> 85 | F20: =+SUM(F21:F27) -> 85 | G20: =+SUM(G21:G27) -> 85 | H20: =+SUM(H21:H27) -> 85 | I20: =+SUM(I21:I27) -> 85 | J20: =+SUM(J21:J27) -> 85 | K20: =+SUM(K21:K27) -> 85 | ... P20: =+SUM(P21:P27) -> 85
C21: < de 29 dias | D21: =+'POBLACION DEMANDANTE POTENCIAL'!D44*80% -> 2.4 | E21: =ROUND(($D$21*(1+$A$7)^(E19-$D$19)),0) -> 2 | F21: =ROUND(($D$21*(1+$A$7)^(F19-$D$19)),0) -> 2 | G21: =ROUND(($D$21*(1+$A$7)^(G19-$D$19)),0) -> 2 | H21: =ROUND(($D$21*(1+$A$7)^(H19-$D$19)),0) -> 2 | I21: =ROUND(($D$21*(1+$A$7)^(I19-$D$19)),0) -> 2 | J21: =ROUND(($D$21*(1+$A$7)^(J19-$D$19)),0) -> 2 | K21: =ROUND(($D$21*(1+$A$7)^(K19-$D$19)),0) -> 2 | L21: =ROUND(($D$21*(1+$A$7)^(L19-$D$19)),0) -> 2 | ... P21: =ROUND(($D$21*(1+$A$7)^(P19-$D$19)),0) -> 2
C22: < de 1 año | D22: =+'POBLACION DEMANDANTE POTENCIAL'!D45*80% -> 5.6 | E22: =ROUND(($D$22*(1+$A$7)^(E19-$D$19)),0) -> 6 | F22: =ROUND(($D$22*(1+$A$7)^(F19-$D$19)),0) -> 6 | G22: =ROUND(($D$22*(1+$A$7)^(G19-$D$19)),0) -> 6 | H22: =ROUND(($D$22*(1+$A$7)^(H19-$D$19)),0) -> 6 | I22: =ROUND(($D$22*(1+$A$7)^(I19-$D$19)),0) -> 6 | J22: =ROUND(($D$22*(1+$A$7)^(J19-$D$19)),0) -> 6 | K22: =ROUND(($D$22*(1+$A$7)^(K19-$D$19)),0) -> 6 | L22: =ROUND(($D$22*(1+$A$7)^(L19-$D$19)),0) -> 6 | ... P22: =ROUND(($D$22*(1+$A$7)^(P19-$D$19)),0) -> 6
C23: 1 año | D23: =+'POBLACION DEMANDANTE POTENCIAL'!D46*80% -> 4 | E23: =ROUND(($D$23*(1+$A$7)^(E19-$D$19)),0) -> 4 | F23: =ROUND(($D$23*(1+$A$7)^(F19-$D$19)),0) -> 4 | G23: =ROUND(($D$23*(1+$A$7)^(G19-$D$19)),0) -> 4 | H23: =ROUND(($D$23*(1+$A$7)^(H19-$D$19)),0) -> 4 | I23: =ROUND(($D$23*(1+$A$7)^(I19-$D$19)),0) -> 4 | J23: =ROUND(($D$23*(1+$A$7)^(J19-$D$19)),0) -> 4 | K23: =ROUND(($D$23*(1+$A$7)^(K19-$D$19)),0) -> 4 | L23: =ROUND(($D$23*(1+$A$7)^(L19-$D$19)),0) -> 4 | ... P23: =ROUND(($D$23*(1+$A$7)^(P19-$D$19)),0) -> 4
C24: 2 años | D24: =+'POBLACION DEMANDANTE POTENCIAL'!D47*80% -> 10.4 | E24: =ROUND(($D$24*(1+$A$7)^(E19-$D$19)),0) -> 10 | F24: =ROUND(($D$24*(1+$A$7)^(F19-$D$19)),0) -> 10 | G24: =ROUND(($D$24*(1+$A$7)^(G19-$D$19)),0) -> 10 | H24: =ROUND(($D$24*(1+$A$7)^(H19-$D$19)),0) -> 10 | I24: =ROUND(($D$24*(1+$A$7)^(I19-$D$19)),0) -> 10 | J24: =ROUND(($D$24*(1+$A$7)^(J19-$D$19)),0) -> 10 | K24: =ROUND(($D$24*(1+$A$7)^(K19-$D$19)),0) -> 10 | L24: =ROUND(($D$24*(1+$A$7)^(L19-$D$19)),0) -> 10 | ... P24: =ROUND(($D$24*(1+$A$7)^(P19-$D$19)),0) -> 10
C25: 3 años | D25: =+'POBLACION DEMANDANTE POTENCIAL'!D48*80% -> 12 | E25: =ROUND(($D$25*(1+$A$7)^(E19-$D$19)),0) -> 12 | F25: =ROUND(($D$25*(1+$A$7)^(F19-$D$19)),0) -> 12 | G25: =ROUND(($D$25*(1+$A$7)^(G19-$D$19)),0) -> 12 | H25: =ROUND(($D$25*(1+$A$7)^(H19-$D$19)),0) -> 12 | I25: =ROUND(($D$25*(1+$A$7)^(I19-$D$19)),0) -> 12 | J25: =ROUND(($D$25*(1+$A$7)^(J19-$D$19)),0) -> 12 | K25: =ROUND(($D$25*(1+$A$7)^(K19-$D$19)),0) -> 12 | L25: =ROUND(($D$25*(1+$A$7)^(L19-$D$19)),0) -> 12 | ... P25: =ROUND(($D$25*(1+$A$7)^(P19-$D$19)),0) -> 12
C26: 4 años | D26: =+'POBLACION DEMANDANTE POTENCIAL'!D49*80% -> 10.4 | E26: =ROUND(($D$26*(1+$A$7)^(E19-$D$19)),0) -> 10 | F26: =ROUND(($D$26*(1+$A$7)^(F19-$D$19)),0) -> 10 | G26: =ROUND(($D$26*(1+$A$7)^(G19-$D$19)),0) -> 10 | H26: =ROUND(($D$26*(1+$A$7)^(H19-$D$19)),0) -> 10 | I26: =ROUND(($D$26*(1+$A$7)^(I19-$D$19)),0) -> 10 | J26: =ROUND(($D$26*(1+$A$7)^(J19-$D$19)),0) -> 10 | K26: =ROUND(($D$26*(1+$A$7)^(K19-$D$19)),0) -> 10 | L26: =ROUND(($D$26*(1+$A$7)^(L19-$D$19)),0) -> 10 | ... P26: =ROUND(($D$26*(1+$A$7)^(P19-$D$19)),0) -> 10
C27: 5 a 11 años | D27: =+'POBLACION DEMANDANTE POTENCIAL'!D50*80% -> 40.8 | E27: =ROUND(($D$27*(1+$A$7)^(E19-$D$19)),0) -> 41 | F27: =ROUND(($D$27*(1+$A$7)^(F19-$D$19)),0) -> 41 | G27: =ROUND(($D$27*(1+$A$7)^(G19-$D$19)),0) -> 41 | H27: =ROUND(($D$27*(1+$A$7)^(H19-$D$19)),0) -> 41 | I27: =ROUND(($D$27*(1+$A$7)^(I19-$D$19)),0) -> 41 | J27: =ROUND(($D$27*(1+$A$7)^(J19-$D$19)),0) -> 41 | K27: =ROUND(($D$27*(1+$A$7)^(K19-$D$19)),0) -> 41 | L27: =ROUND(($D$27*(1+$A$7)^(L19-$D$19)),0) -> 41 | ... P27: =ROUND(($D$27*(1+$A$7)^(P19-$D$19)),0) -> 41
C29: POBLACION SUJETO DE INTERVENCION | D29: PERIODO DE INVERSION | G29: PERIODO DE POST INVERSION
D30: 0 | G30: 1 | H30: 2 | I30: 3 | J30: 4 | K30: 5 | L30: 6 | M30: 7 | N30: 8 | O30: 9 | P30: 10
D31: =+D19 -> 2024 | E31: =+E19 -> 2025 | F31: =+F19 -> 2026 | G31: =+G19 -> 2027 | H31: =+H19 -> 2028 | I31: =+I19 -> 2029 | J31: =+J19 -> 2030 | K31: =+K19 -> 2031 | ... P31: =+P19 -> 2036
C32: ESTIMULACION TEMPRANA (< de 3 años) | D32: =+SUM(D33:D37) -> 34.4 | E32: =+SUM(E33:E37) -> 34 | F32: =+SUM(F33:F37) -> 34 | G32: =+SUM(G33:G37) -> 34 | H32: =+SUM(H33:H37) -> 34 | I32: =+SUM(I33:I37) -> 34 | J32: =+SUM(J33:J37) -> 34 | K32: =+SUM(K33:K37) -> 34 | ... P32: =+SUM(P33:P37) -> 34
C33: < 29 dias | D33: =+'POBLACION DEMANDANTE POTENCIAL'!D56*80% -> 2.4 | E33: =ROUND(($D$33*(1+$A$7)^(E31-$D$31)),0) -> 2 | F33: =ROUND(($D$33*(1+$A$7)^(F31-$D$31)),0) -> 2 | G33: =ROUND(($D$33*(1+$A$7)^(G31-$D$31)),0) -> 2 | H33: =ROUND(($D$33*(1+$A$7)^(H31-$D$31)),0) -> 2 | I33: =ROUND(($D$33*(1+$A$7)^(I31-$D$31)),0) -> 2 | J33: =ROUND(($D$33*(1+$A$7)^(J31-$D$31)),0) -> 2 | K33: =ROUND(($D$33*(1+$A$7)^(K31-$D$31)),0) -> 2 | L33: =ROUND(($D$33*(1+$A$7)^(L31-$D$31)),0) -> 2 | ... P33: =ROUND(($D$33*(1+$A$7)^(P31-$D$31)),0) -> 2
C34: < 1 año | D34: =+'POBLACION DEMANDANTE POTENCIAL'!D57*80% -> 5.6 | E34: =ROUND(($D$34*(1+$A$7)^(E31-$D$31)),0) -> 6 | F34: =ROUND(($D$34*(1+$A$7)^(F31-$D$31)),0) -> 6 | G34: =ROUND(($D$34*(1+$A$7)^(G31-$D$31)),0) -> 6 | H34: =ROUND(($D$34*(1+$A$7)^(H31-$D$31)),0) -> 6 | I34: =ROUND(($D$34*(1+$A$7)^(I31-$D$31)),0) -> 6 | J34: =ROUND(($D$34*(1+$A$7)^(J31-$D$31)),0) -> 6 | K34: =ROUND(($D$34*(1+$A$7)^(K31-$D$31)),0) -> 6 | L34: =ROUND(($D$34*(1+$A$7)^(L31-$D$31)),0) -> 6 | ... P34: =ROUND(($D$34*(1+$A$7)^(P31-$D$31)),0) -> 6
C35: 1 años | D35: =+'POBLACION DEMANDANTE POTENCIAL'!D58*80% -> 4 | E35: =ROUND(($D$35*(1+$A$7)^(E31-$D$31)),0) -> 4 | F35: =ROUND(($D$35*(1+$A$7)^(F31-$D$31)),0) -> 4 | G35: =ROUND(($D$35*(1+$A$7)^(G31-$D$31)),0) -> 4 | H35: =ROUND(($D$35*(1+$A$7)^(H31-$D$31)),0) -> 4 | I35: =ROUND(($D$35*(1+$A$7)^(I31-$D$31)),0) -> 4 | J35: =ROUND(($D$35*(1+$A$7)^(J31-$D$31)),0) -> 4 | K35: =ROUND(($D$35*(1+$A$7)^(K31-$D$31)),0) -> 4 | L35: =ROUND(($D$35*(1+$A$7)^(L31-$D$31)),0) -> 4 | ... P35: =ROUND(($D$35*(1+$A$7)^(P31-$D$31)),0) -> 4
C36: 2 años | D36: =+'POBLACION DEMANDANTE POTENCIAL'!D59*80% -> 10.4 | E36: =ROUND((D36*(1+$A$7)^(E31-$D$31)),0) -> 10 | F36: =ROUND((E36*(1+$A$7)^(F31-$D$31)),0) -> 10 | G36: =ROUND((F36*(1+$A$7)^(G31-$D$31)),0) -> 10 | H36: =ROUND((G36*(1+$A$7)^(H31-$D$31)),0) -> 10 | I36: =ROUND((H36*(1+$A$7)^(I31-$D$31)),0) -> 10 | J36: =ROUND((I36*(1+$A$7)^(J31-$D$31)),0) -> 10 | K36: =ROUND((J36*(1+$A$7)^(K31-$D$31)),0) -> 10 | L36: =ROUND((K36*(1+$A$7)^(L31-$D$31)),0) -> 10 | ... P36: =ROUND((O36*(1+$A$7)^(P31-$D$31)),0) -> 10
C37: 3 años | D37: =+'POBLACION DEMANDANTE POTENCIAL'!D60*80% -> 12 | E37: =ROUND((D37*(1+$A$7)^(E31-$D$31)),0) -> 12 | F37: =ROUND((E37*(1+$A$7)^(F31-$D$31)),0) -> 12 | G37: =ROUND((F37*(1+$A$7)^(G31-$D$31)),0) -> 12 | H37: =ROUND((G37*(1+$A$7)^(H31-$D$31)),0) -> 12 | I37: =ROUND((H37*(1+$A$7)^(I31-$D$31)),0) -> 12 | J37: =ROUND((I37*(1+$A$7)^(J31-$D$31)),0) -> 12 | K37: =ROUND((J37*(1+$A$7)^(K31-$D$31)),0) -> 12 | L37: =ROUND((K37*(1+$A$7)^(L31-$D$31)),0) -> 12 | ... P37: =ROUND((O37*(1+$A$7)^(P31-$D$31)),0) -> 12
C39: POBLACION SUJETO DE INTERVENCION | D39: PERIODO DE INVERSION | G39: PERIODO DE POST INVERSION
D40: 0 | G40: 1 | H40: 2 | I40: 3 | J40: 4 | K40: 5 | L40: 6 | M40: 7 | N40: 8 | O40: 9 | P40: 10
D41: 2024 | E41: 2025 | F41: 2026 | G41: 2027 | H41: 2028 | I41: 2029 | J41: 2030 | K41: 2031 | L41: 2032 | M41: 2033 | N41: 2034 | O41: 2035 | P41: 2036
C42: INMUNIZACIONES (< de 4 años, Gestantes) | D42: =+SUM(D43:D48) -> 56.8 | E42: =+SUM(E43:E48) -> 56 | F42: =+SUM(F43:F48) -> 56 | G42: =+SUM(G43:G48) -> 56 | H42: =+SUM(H43:H48) -> 56 | I42: =+SUM(I43:I48) -> 56 | J42: =+SUM(J43:J48) -> 56 | K42: =+SUM(K43:K48) -> 56 | ... P42: =+SUM(P43:P48) -> 56
C43: < 1 año | D43: =+'POBLACION DEMANDANTE POTENCIAL'!D66*80% -> 5.6 | E43: =ROUND(($D$43*(1+$A$7)^(E41-$D$41)),0) -> 6 | F43: =ROUND(($D$43*(1+$A$7)^(F41-$D$41)),0) -> 6 | G43: =ROUND(($D$43*(1+$A$7)^(G41-$D$41)),0) -> 6 | H43: =ROUND(($D$43*(1+$A$7)^(H41-$D$41)),0) -> 6 | I43: =ROUND(($D$43*(1+$A$7)^(I41-$D$41)),0) -> 6 | J43: =ROUND(($D$43*(1+$A$7)^(J41-$D$41)),0) -> 6 | K43: =ROUND(($D$43*(1+$A$7)^(K41-$D$41)),0) -> 6 | L43: =ROUND(($D$43*(1+$A$7)^(L41-$D$41)),0) -> 6 | ... P43: =ROUND(($D$43*(1+$A$7)^(P41-$D$41)),0) -> 6
C44: 1 año | D44: =+'POBLACION DEMANDANTE POTENCIAL'!D67*80% -> 4 | E44: =ROUND(($D$44*(1+$A$7)^(E41-$D$41)),0) -> 4 | F44: =ROUND(($D$44*(1+$A$7)^(F41-$D$41)),0) -> 4 | G44: =ROUND(($D$44*(1+$A$7)^(G41-$D$41)),0) -> 4 | H44: =ROUND(($D$44*(1+$A$7)^(H41-$D$41)),0) -> 4 | I44: =ROUND(($D$44*(1+$A$7)^(I41-$D$41)),0) -> 4 | J44: =ROUND(($D$44*(1+$A$7)^(J41-$D$41)),0) -> 4 | K44: =ROUND(($D$44*(1+$A$7)^(K41-$D$41)),0) -> 4 | L44: =ROUND(($D$44*(1+$A$7)^(L41-$D$41)),0) -> 4 | ... P44: =ROUND(($D$44*(1+$A$7)^(P41-$D$41)),0) -> 4
C45: 2 años | D45: =+'POBLACION DEMANDANTE POTENCIAL'!D68*80% -> 10.4 | E45: =ROUND(($D$45*(1+$A$7)^(E41-$D$41)),0) -> 10 | F45: =ROUND(($D$45*(1+$A$7)^(F41-$D$41)),0) -> 10 | G45: =ROUND(($D$45*(1+$A$7)^(G41-$D$41)),0) -> 10 | H45: =ROUND(($D$45*(1+$A$7)^(H41-$D$41)),0) -> 10 | I45: =ROUND(($D$45*(1+$A$7)^(I41-$D$41)),0) -> 10 | J45: =ROUND(($D$45*(1+$A$7)^(J41-$D$41)),0) -> 10 | K45: =ROUND(($D$45*(1+$A$7)^(K41-$D$41)),0) -> 10 | L45: =ROUND(($D$45*(1+$A$7)^(L41-$D$41)),0) -> 10 | ... P45: =ROUND(($D$45*(1+$A$7)^(P41-$D$41)),0) -> 10
C46: 3 años | D46: =+'POBLACION DEMANDANTE POTENCIAL'!D69*80% -> 12 | E46: =ROUND(($D$46*(1+$A$7)^(E41-$D$41)),0) -> 12 | F46: =ROUND(($D$46*(1+$A$7)^(F41-$D$41)),0) -> 12 | G46: =ROUND(($D$46*(1+$A$7)^(G41-$D$41)),0) -> 12 | H46: =ROUND(($D$46*(1+$A$7)^(H41-$D$41)),0) -> 12 | I46: =ROUND(($D$46*(1+$A$7)^(I41-$D$41)),0) -> 12 | J46: =ROUND(($D$46*(1+$A$7)^(J41-$D$41)),0) -> 12 | K46: =ROUND(($D$46*(1+$A$7)^(K41-$D$41)),0) -> 12 | L46: =ROUND(($D$46*(1+$A$7)^(L41-$D$41)),0) -> 12 | ... P46: =ROUND(($D$46*(1+$A$7)^(P41-$D$41)),0) -> 12
C47: 4 años | D47: =+'POBLACION DEMANDANTE POTENCIAL'!D70*80% -> 10.4 | E47: =ROUND(($D$47*(1+$A$7)^(E41-$D$41)),0) -> 10 | F47: =ROUND(($D$47*(1+$A$7)^(F41-$D$41)),0) -> 10 | G47: =ROUND(($D$47*(1+$A$7)^(G41-$D$41)),0) -> 10 | H47: =ROUND(($D$47*(1+$A$7)^(H41-$D$41)),0) -> 10 | I47: =ROUND(($D$47*(1+$A$7)^(I41-$D$41)),0) -> 10 | J47: =ROUND(($D$47*(1+$A$7)^(J41-$D$41)),0) -> 10 | K47: =ROUND(($D$47*(1+$A$7)^(K41-$D$41)),0) -> 10 | L47: =ROUND(($D$47*(1+$A$7)^(L41-$D$41)),0) -> 10 | ... P47: =ROUND(($D$47*(1+$A$7)^(P41-$D$41)),0) -> 10
C48: Gestantes | D48: =+'POBLACION DEMANDANTE POTENCIAL'!D71*80% -> 14.4 | E48: =ROUND(($D$48*(1+$A$7)^(E41-$D$41)),0) -> 14 | F48: =ROUND(($D$48*(1+$A$7)^(F41-$D$41)),0) -> 14 | G48: =ROUND(($D$48*(1+$A$7)^(G41-$D$41)),0) -> 14 | H48: =ROUND(($D$48*(1+$A$7)^(H41-$D$41)),0) -> 14 | I48: =ROUND(($D$48*(1+$A$7)^(I41-$D$41)),0) -> 14 | J48: =ROUND(($D$48*(1+$A$7)^(J41-$D$41)),0) -> 14 | K48: =ROUND(($D$48*(1+$A$7)^(K41-$D$41)),0) -> 14 | L48: =ROUND(($D$48*(1+$A$7)^(L41-$D$41)),0) -> 14 | ... P48: =ROUND(($D$48*(1+$A$7)^(P41-$D$41)),0) -> 14
...

Sheet DEMANDA SERV. DE SALUD SN PY
A1: =+Hoja3!C23 -> 0.0019 | B1: DEMANDA DE LOS SERVICIOS DE SALUD: ATENCIONES DE PROMOCION (SIN PROYECTO)
C3: RATIO DE CONCENTRACION
C4: ATENCIONES PREVENTIVAS | D4: GRUPOS | E4: CONCENTRACION (DE ATENCION/PERSONA) SIN PROYECTO
C5: MEDICINA GENERAL | D5: =+C11 -> 0 a 85 años a mas | E5: 2
C7: POBLACION SUJETO DE INTERVENCION (PERSONAS EN SUS DIFERENTES ETAPAS DE VIDA) | D7: PERIODO DE INVERSION | G7: PERIODO DE POST INVERSION
D8: 0 | G8: 1 | H8: 2 | I8: 3 | J8: 4 | K8: 5 | L8: 6 | M8: 7 | N8: 8 | O8: 9 | P8: 10
A9: =+'POBLACION DEMANDANTE EFECTIVA'!A7 -> 0.0003 | D9: 2024 | E9: 2025 | F9: 2026 | G9: 2027 | H9: 2028 | I9: 2029 | J9: 2030 | K9: 2031 | L9: 2032 | M9: 2033 | N9: 2034 | O9: 2035 | P9: 2036
C10: Medicina General | D10: =+D11 -> 340.704 | E10: =+E11 -> 341 | F10: =+F11 -> 341 | G10: =+G11 -> 341 | H10: =+H11 -> 341 | I10: =+I11 -> 341 | J10: =+J11 -> 341 | K10: =+K11 -> 341 | ... P10: =+P11 -> 342
C11: 0 a 85 años a mas | D11: =+'POBLACION DEMANDANTE EFECTIVA'!D9*E5 -> 340.704 | E11: =ROUND(($D$11*(1+$A$9)^(E9-$D$9)),0) -> 341 | F11: =ROUND(($D$11*(1+$A$9)^(F9-$D$9)),0) -> 341 | G11: =ROUND(($D$11*(1+$A$9)^(G9-$D$9)),0) -> 341 | H11: =ROUND(($D$11*(1+$A$9)^(H9-$D$9)),0) -> 341 | I11: =ROUND(($D$11*(1+$A$9)^(I9-$D$9)),0) -> 341 | J11: =ROUND(($D$11*(1+$A$9)^(J9-$D$9)),0) -> 341 | K11: =ROUND(($D$11*(1+$A$9)^(K9-$D$9)),0) -> 341 | L11: =ROUND(($D$11*(1+$A$9)^(L9-$D$9)),0) -> 342 | ... P11: =ROUND(($D$11*(1+$A$9)^(P9-$D$9)),0) -> 342
C13: RATIO DE CONCENTRACION
C14: ATENCIONES PREVENTIVAS | D14: GRUPOS | E14: CONCENTRACION (DE ATENCION/PERSONA) SIN PROYECTO
C15: TELECONSULTA MEDICA | D15: =+C21 -> 0 a 85 años a mas | E15: 1
C17: POBLACION SUJETO DE INTERVENCION (PERSONAS EN SUS DIFERENTES ETAPAS DE VIDA) | D17: PERIODO DE INVERSION | G17: PERIODO DE POST INVERSION
D18: 0 | G18: 1 | H18: 2 | I18: 3 | J18: 4 | K18: 5 | L18: 6 | M18: 7 | N18: 8 | O18: 9 | P18: 10
D19: 2024 | E19: 2025 | F19: 2026 | G19: 2027 | H19: 2028 | I19: 2029 | J19: 2030 | K19: 2031 | L19: 2032 | M19: 2033 | N19: 2034 | O19: 2035 | P19: 2036
C20: Teleconsulta medica | D20: =+D21 -> 170.352 | E20: =+E21 -> 170 | F20: =+F21 -> 170 | G20: =+G21 -> 171 | H20: =+H21 -> 171 | I20: =+I21 -> 171 | J20: =+J21 -> 171 | K20: =+K21 -> 171 | ... P20: =+P21 -> 171
C21: 0 a 85 años a mas | D21: =+'POBLACION DEMANDANTE EFECTIVA'!D15*E15 -> 170.352 | E21: =ROUND(($D$21*(1+$A$9)^(E19-$D$19)),0) -> 170 | F21: =ROUND(($D$21*(1+$A$9)^(F19-$D$19)),0) -> 170 | G21: =ROUND(($D$21*(1+$A$9)^(G19-$D$19)),0) -> 171 | H21: =ROUND(($D$21*(1+$A$9)^(H19-$D$19)),0) -> 171 | I21: =ROUND(($D$21*(1+$A$9)^(I19-$D$19)),0) -> 171 | J21: =ROUND(($D$21*(1+$A$9)^(J19-$D$19)),0) -> 171 | K21: =ROUND(($D$21*(1+$A$9)^(K19-$D$19)),0) -> 171 | L21: =ROUND(($D$21*(1+$A$9)^(L19-$D$19)),0) -> 171 | ... P21: =ROUND(($D$21*(1+$A$9)^(P19-$D$19)),0) -> 171
C23: RATIO DE CONCENTRACION
C24: ATENCIONES PREVENTIVAS | D24: GRUPOS | E24: CONCENTRACION (DE ATENCION/PERSONA) SIN PROYECTO
C25: CONTROLES DE CRECIMIENTO Y DESARROLLO (CRED) | D25: < de 29 dias | E25: 2
D26: < de 1 año | E26: 6
D27: 1 año | E27: 4
D28: 2 años | E28: 2
D29: 3 años | E29: 2
D30: 4 años | E30: 2
D31: 5 a 11 años | E31: 1
C33: POBLACION SUJETO DE INTERVENCION | D33: PERIODO DE INVERSION | G33: PERIODO DE POST INVERSION
D34: 0 | G34: 1 | H34: 2 | I34: 3 | J34: 4 | K34: 5 | L34: 6 | M34: 7 | N34: 8 | O34: 9 | P34: 10
D35: =+D19 -> 2024 | E35: =+E19 -> 2025 | F35: =+F19 -> 2026 | G35: =+G19 -> 2027 | H35: =+H19 -> 2028 | I35: =+I19 -> 2029 | J35: =+J19 -> 2030 | K35: =+K19 -> 2031 | ... P35: =+P19 -> 2036
C36: CRED (< de 11 años) | D36: =+SUM(D37:D43) -> 160.8 | E36: =+SUM(E37:E43) -> 162 | F36: =+SUM(F37:F43) -> 162 | G36: =+SUM(G37:G43) -> 162 | H36: =+SUM(H37:H43) -> 162 | I36: =+SUM(I37:I43) -> 162 | J36: =+SUM(J37:J43) -> 162 | K36: =+SUM(K37:K43) -> 162 | ... P36: =+SUM(P37:P43) -> 162
C37: < de 29 dias | D37: =+'POBLACION DEMANDANTE EFECTIVA'!D21*E25 -> 4.8 | E37: =ROUND(($D$37*(1+$A$9)^(E35-$D$35)),0) -> 5 | F37: =ROUND(($D$37*(1+$A$9)^(F35-$D$35)),0) -> 5 | G37: =ROUND(($D$37*(1+$A$9)^(G35-$D$35)),0) -> 5 | H37: =ROUND(($D$37*(1+$A$9)^(H35-$D$35)),0) -> 5 | I37: =ROUND(($D$37*(1+$A$9)^(I35-$D$35)),0) -> 5 | J37: =ROUND(($D$37*(1+$A$9)^(J35-$D$35)),0) -> 5 | K37: =ROUND(($D$37*(1+$A$9)^(K35-$D$35)),0) -> 5 | L37: =ROUND(($D$37*(1+$A$9)^(L35-$D$35)),0) -> 5 | ... P37: =ROUND(($D$37*(1+$A$9)^(P35-$D$35)),0) -> 5
C38: < de 1 año | D38: =+'POBLACION DEMANDANTE EFECTIVA'!D22*E26 -> 33.6 | E38: =ROUND(($D$38*(1+$A$9)^(E35-$D$35)),0) -> 34 | F38: =ROUND(($D$38*(1+$A$9)^(F35-$D$35)),0) -> 34 | G38: =ROUND(($D$38*(1+$A$9)^(G35-$D$35)),0) -> 34 | H38: =ROUND(($D$38*(1+$A$9)^(H35-$D$35)),0) -> 34 | I38: =ROUND(($D$38*(1+$A$9)^(I35-$D$35)),0) -> 34 | J38: =ROUND(($D$38*(1+$A$9)^(J35-$D$35)),0) -> 34 | K38: =ROUND(($D$38*(1+$A$9)^(K35-$D$35)),0) -> 34 | L38: =ROUND(($D$38*(1+$A$9)^(L35-$D$35)),0) -> 34 | ... P38: =ROUND(($D$38*(1+$A$9)^(P35-$D$35)),0) -> 34
C39: 1 año | D39: =+'POBLACION DEMANDANTE EFECTIVA'!D23*E27 -> 16 | E39: =ROUND(($D$39*(1+$A$9)^(E35-$D$35)),0) -> 16 | F39: =ROUND(($D$39*(1+$A$9)^(F35-$D$35)),0) -> 16 | G39: =ROUND(($D$39*(1+$A$9)^(G35-$D$35)),0) -> 16 | H39: =ROUND(($D$39*(1+$A$9)^(H35-$D$35)),0) -> 16 | I39: =ROUND(($D$39*(1+$A$9)^(I35-$D$35)),0) -> 16 | J39: =ROUND(($D$39*(1+$A$9)^(J35-$D$35)),0) -> 16 | K39: =ROUND(($D$39*(1+$A$9)^(K35-$D$35)),0) -> 16 | L39: =ROUND(($D$39*(1+$A$9)^(L35-$D$35)),0) -> 16 | ... P39: =ROUND(($D$39*(1+$A$9)^(P35-$D$35)),0) -> 16
C40: 2 años | D40: =+'POBLACION DEMANDANTE EFECTIVA'!D24*E28 -> 20.8 | E40: =ROUND(($D$40*(1+$A$9)^(E35-$D$35)),0) -> 21 | F40: =ROUND(($D$40*(1+$A$9)^(F35-$D$35)),0) -> 21 | G40: =ROUND(($D$40*(1+$A$9)^(G35-$D$35)),0) -> 21 | H40: =ROUND(($D$40*(1+$A$9)^(H35-$D$35)),0) -> 21 | I40: =ROUND(($D$40*(1+$A$9)^(I35-$D$35)),0) -> 21 | J40: =ROUND(($D$40*(1+$A$9)^(J35-$D$35)),0) -> 21 | K40: =ROUND(($D$40*(1+$A$9)^(K35-$D$35)),0) -> 21 | L40: =ROUND(($D$40*(1+$A$9)^(L35-$D$35)),0) -> 21 | ... P40: =ROUND(($D$40*(1+$A$9)^(P35-$D$35)),0) -> 21
C41: 3 años | D41: =+'POBLACION DEMANDANTE EFECTIVA'!D25*E29 -> 24 | E41: =ROUND(($D$41*(1+$A$9)^(E35-$D$35)),0) -> 24 | F41: =ROUND(($D$41*(1+$A$9)^(F35-$D$35)),0) -> 24 | G41: =ROUND(($D$41*(1+$A$9)^(G35-$D$35)),0) -> 24 | H41: =ROUND(($D$41*(1+$A$9)^(H35-$D$35)),0) -> 24 | I41: =ROUND(($D$41*(1+$A$9)^(I35-$D$35)),0) -> 24 | J41: =ROUND(($D$41*(1+$A$9)^(J35-$D$35)),0) -> 24 | K41: =ROUND(($D$41*(1+$A$9)^(K35-$D$35)),0) -> 24 | L41: =ROUND(($D$41*(1+$A$9)^(L35-$D$35)),0) -> 24 | ... P41: =ROUND(($D$41*(1+$A$9)^(P35-$D$35)),0) -> 24
C42: 4 años | D42: =+'POBLACION DEMANDANTE EFECTIVA'!D26*E30 -> 20.8 | E42: =ROUND(($D$42*(1+$A$9)^(E35-$D$35)),0) -> 21 | F42: =ROUND(($D$42*(1+$A$9)^(F35-$D$35)),0) -> 21 | G42: =ROUND(($D$42*(1+$A$9)^(G35-$D$35)),0) -> 21 | H42: =ROUND(($D$42*(1+$A$9)^(H35-$D$35)),0) -> 21 | I42: =ROUND(($D$42*(1+$A$9)^(I35-$D$35)),0) -> 21 | J42: =ROUND(($D$42*(1+$A$9)^(J35-$D$35)),0) -> 21 | K42: =ROUND(($D$42*(1+$A$9)^(K35-$D$35)),0) -> 21 | L42: =ROUND(($D$42*(1+$A$9)^(L35-$D$35)),0) -> 21 | ... P42: =ROUND(($D$42*(1+$A$9)^(P35-$D$35)),0) -> 21
C43: 5 a 11 años | D43: =+'POBLACION DEMANDANTE EFECTIVA'!D27*E31 -> 40.8 | E43: =ROUND(($D$43*(1+$A$9)^(E35-$D$35)),0) -> 41 | F43: =ROUND(($D$43*(1+$A$9)^(F35-$D$35)),0) -> 41 | G43: =ROUND(($D$43*(1+$A$9)^(G35-$D$35)),0) -> 41 | H43: =ROUND(($D$43*(1+$A$9)^(H35-$D$35)),0) -> 41 | I43: =ROUND(($D$43*(1+$A$9)^(I35-$D$35)),0) -> 41 | J43: =ROUND(($D$43*(1+$A$9)^(J35-$D$35)),0) -> 41 | K43: =ROUND(($D$43*(1+$A$9)^(K35-$D$35)),0) -> 41 | L43: =ROUND(($D$43*(1+$A$9)^(L35-$D$35)),0) -> 41 | ... P43: =ROUND(($D$43*(1+$A$9)^(P35-$D$35)),0) -> 41
C45: RATIO DE CONCENTRACION
C46: ATENCIONES PREVENTIVAS | D46: GRUPOS | E46: CONCENTRACION (DE ATENCION/PERSONA) SIN PROYECTO
C47: ESTIMULACION TEMPRANA | D47: =+C57 -> < 29 dias | E47: 1
...

Sheet DEMANDA SERV. DE SALUD CN PY
C3: RATIO DE CONCENTRACION
C4: ATENCIONES PREVENTIVAS | D4: GRUPOS | E4: CONCENTRACION (DE ATENCION/PERSONA) CON PROYECTO
C5: MEDICINA GENERAL | D5: =+C11 -> 0 a 85 años a mas | E5: 3
C7: POBLACION SUJETO DE INTERVENCION (PERSONAS EN SUS DIFERENTES ETAPAS DE VIDA) | D7: PERIODO DE INVERSION | G7: PERIODO DE POST INVERSION
D8: 0 | G8: 1 | H8: 2 | I8: 3 | J8: 4 | K8: 5 | L8: 6 | M8: 7 | N8: 8 | O8: 9 | P8: 10
A9: =+Hoja1!D17 -> 0.0003 | D9: 2024 | E9: 2025 | F9: 2026 | G9: 2027 | H9: 2028 | I9: 2029 | J9: 2030 | K9: 2031 | L9: 2032 | M9: 2033 | N9: 2034 | O9: 2035 | P9: 2036
C10: Medicina General | D10: =+D11 -> 511.056 | E10: =+E11 -> 511 | F10: =+F11 -> 511 | G10: =+G11 -> 512 | H10: =+H11 -> 512 | I10: =+I11 -> 512 | J10: =+J11 -> 512 | K10: =+K11 -> 512 | ... P10: =+P11 -> 513
C11: 0 a 85 años a mas | D11: =+'POBLACION DEMANDANTE EFECTIVA'!D9*E5 -> 511.056 | E11: =ROUND(($D$11*(1+$A$9)^(E9-$D$9)),0) -> 511 | F11: =ROUND(($D$11*(1+$A$9)^(F9-$D$9)),0) -> 511 | G11: =ROUND(($D$11*(1+$A$9)^(G9-$D$9)),0) -> 512 | H11: =ROUND(($D$11*(1+$A$9)^(H9-$D$9)),0) -> 512 | I11: =ROUND(($D$11*(1+$A$9)^(I9-$D$9)),0) -> 512 | J11: =ROUND(($D$11*(1+$A$9)^(J9-$D$9)),0) -> 512 | K11: =ROUND(($D$11*(1+$A$9)^(K9-$D$9)),0) -> 512 | L11: =ROUND(($D$11*(1+$A$9)^(L9-$D$9)),0) -> 512 | ... P11: =ROUND(($D$11*(1+$A$9)^(P9-$D$9)),0) -> 513
C13: RATIO DE CONCENTRACION
C14: ATENCIONES PREVENTIVAS | D14: GRUPOS | E14: CONCENTRACION (DE ATENCION/PERSONA) CON PROYECTO
C15: TELECONSULTA MEDICA | D15: =+C21 -> 0 a 85 años a mas | E15: 2
C17: POBLACION SUJETO DE INTERVENCION (PERSONAS EN SUS DIFERENTES ETAPAS DE VIDA) | D17: PERIODO DE INVERSION | G17: PERIODO DE POST INVERSION
D18: 0 | G18: 1 | H18: 2 | I18: 3 | J18: 4 | K18: 5 | L18: 6 | M18: 7 | N18: 8 | O18: 9 | P18: 10
D19: 2024 | E19: 2025 | F19: 2026 | G19: 2027 | H19: 2028 | I19: 2029 | J19: 2030 | K19: 2031 | L19: 2032 | M19: 2033 | N19: 2034 | O19: 2035 | P19: 2036
C20: Teleconsulta medica | D20: =+D21 -> 340.704 | E20: =+E21 -> 341 | F20: =+F21 -> 341 | G20: =+G21 -> 341 | H20: =+H21 -> 341 | I20: =+I21 -> 341 | J20: =+J21 -> 341 | K20: =+K21 -> 341 | ... P20: =+P21 -> 342
C21: 0 a 85 años a mas | D21: =+'POBLACION DEMANDANTE EFECTIVA'!D15*E15 -> 340.704 | E21: =ROUND(($D$21*(1+$A$9)^(E19-$D$19)),0) -> 341 | F21: =ROUND(($D$21*(1+$A$9)^(F19-$D$19)),0) -> 341 | G21: =ROUND(($D$21*(1+$A$9)^(G19-$D$19)),0) -> 341 | H21: =ROUND(($D$21*(1+$A$9)^(H19-$D$19)),0) -> 341 | I21: =ROUND(($D$21*(1+$A$9)^(I19-$D$19)),0) -> 341 | J21: =ROUND(($D$21*(1+$A$9)^(J19-$D$19)),0) -> 341 | K21: =ROUND(($D$21*(1+$A$9)^(K19-$D$19)),0) -> 341 | L21: =ROUND(($D$21*(1+$A$9)^(L19-$D$19)),0) -> 342 | ... P21: =ROUND(($D$21*(1+$A$9)^(P19-$D$19)),0) -> 342
C23: RATIO DE CONCENTRACION - ATENCIONES PREVENTIVAS
C24: ATENCIONES PREVENTIVAS | D24: GRUPOS | E24: CONCENTRACION (DE ATENCION/PERSONA) CON PROYECTO
C25: CONTROLES DE CRECIMIENTO Y DESARROLLO (CRED) | D25: < de 29 dias | E25: 2
D26: < de 1 año | E26: 6
D27: 1 año | E27: 4
D28: 2 años | E28: 2
D29: 3 años | E29: 2
D30: 4 años | E30: 2
D31: 5 a 11 años | E31: 1
C33: POBLACION SUJETO DE INTERVENCION | D33: PERIODO DE INVERSION | G33: PERIODO DE POST INVERSION
D34: 0 | G34: 1 | H34: 2 | I34: 3 | J34: 4 | K34: 5 | L34: 6 | M34: 7 | N34: 8 | O34: 9 | P34: 10
D35: =+D19 -> 2024 | E35: =+E19 -> 2025 | F35: =+F19 -> 2026 | G35: =+G19 -> 2027 | H35: =+H19 -> 2028 | I35: =+I19 -> 2029 | J35: =+J19 -> 2030 | K35: =+K19 -> 2031 | ... P35: =+P19 -> 2036
C36: CRED (< de 11 años) | D36: =+SUM(D37:D43) -> 160.8 | E36: =+SUM(E37:E43) -> 162 | F36: =+SUM(F37:F43) -> 162 | G36: =+SUM(G37:G43) -> 162 | H36: =+SUM(H37:H43) -> 162 | I36: =+SUM(I37:I43) -> 162 | J36: =+SUM(J37:J43) -> 162 | K36: =+SUM(K37:K43) -> 162 | ... P36: =+SUM(P37:P43) -> 162
C37: < de 29 dias | D37: =+'POBLACION DEMANDANTE EFECTIVA'!D21*E25 -> 4.8 | E37: =ROUND(($D$37*(1+$A$9)^(E35-$D$35)),0) -> 5 | F37: =ROUND(($D$37*(1+$A$9)^(F35-$D$35)),0) -> 5 | G37: =ROUND(($D$37*(1+$A$9)^(G35-$D$35)),0) -> 5 | H37: =ROUND(($D$37*(1+$A$9)^(H35-$D$35)),0) -> 5 | I37: =ROUND(($D$37*(1+$A$9)^(I35-$D$35)),0) -> 5 | J37: =ROUND(($D$37*(1+$A$9)^(J35-$D$35)),0) -> 5 | K37: =ROUND(($D$37*(1+$A$9)^(K35-$D$35)),0) -> 5 | L37: =ROUND(($D$37*(1+$A$9)^(L35-$D$35)),0) -> 5 | ... P37: =ROUND(($D$37*(1+$A$9)^(P35-$D$35)),0) -> 5
C38: < de 1 año | D38: =+'POBLACION DEMANDANTE EFECTIVA'!D22*E26 -> 33.6 | E38: =ROUND(($D$38*(1+$A$9)^(E35-$D$35)),0) -> 34 | F38: =ROUND(($D$38*(1+$A$9)^(F35-$D$35)),0) -> 34 | G38: =ROUND(($D$38*(1+$A$9)^(G35-$D$35)),0) -> 34 | H38: =ROUND(($D$38*(1+$A$9)^(H35-$D$35)),0) -> 34 | I38: =ROUND(($D$38*(1+$A$9)^(I35-$D$35)),0) -> 34 | J38: =ROUND(($D$38*(1+$A$9)^(J35-$D$35)),0) -> 34 | K38: =ROUND(($D$38*(1+$A$9)^(K35-$D$35)),0) -> 34 | L38: =ROUND(($D$38*(1+$A$9)^(L35-$D$35)),0) -> 34 | ... P38: =ROUND(($D$38*(1+$A$9)^(P35-$D$35)),0) -> 34
C39: 1 año | D39: =+'POBLACION DEMANDANTE EFECTIVA'!D23*E27 -> 16 | E39: =ROUND(($D$39*(1+$A$9)^(E35-$D$35)),0) -> 16 | F39: =ROUND(($D$39*(1+$A$9)^(F35-$D$35)),0) -> 16 | G39: =ROUND(($D$39*(1+$A$9)^(G35-$D$35)),0) -> 16 | H39: =ROUND(($D$39*(1+$A$9)^(H35-$D$35)),0) -> 16 | I39: =ROUND(($D$39*(1+$A$9)^(I35-$D$35)),0) -> 16 | J39: =ROUND(($D$39*(1+$A$9)^(J35-$D$35)),0) -> 16 | K39: =ROUND(($D$39*(1+$A$9)^(K35-$D$35)),0) -> 16 | L39: =ROUND(($D$39*(1+$A$9)^(L35-$D$35)),0) -> 16 | ... P39: =ROUND(($D$39*(1+$A$9)^(P35-$D$35)),0) -> 16
C40: 2 años | D40: =+'POBLACION DEMANDANTE EFECTIVA'!D24*E28 -> 20.8 | E40: =ROUND(($D$40*(1+$A$9)^(E35-$D$35)),0) -> 21 | F40: =ROUND(($D$40*(1+$A$9)^(F35-$D$35)),0) -> 21 | G40: =ROUND(($D$40*(1+$A$9)^(G35-$D$35)),0) -> 21 | H40: =ROUND(($D$40*(1+$A$9)^(H35-$D$35)),0) -> 21 | I40: =ROUND(($D$40*(1+$A$9)^(I35-$D$35)),0) -> 21 | J40: =ROUND(($D$40*(1+$A$9)^(J35-$D$35)),0) -> 21 | K40: =ROUND(($D$40*(1+$A$9)^(K35-$D$35)),0) -> 21 | L40: =ROUND(($D$40*(1+$A$9)^(L35-$D$35)),0) -> 21 | ... P40: =ROUND(($D$40*(1+$A$9)^(P35-$D$35)),0) -> 21
C41: 3 años | D41: =+'POBLACION DEMANDANTE EFECTIVA'!D25*E29 -> 24 | E41: =ROUND(($D$41*(1+$A$9)^(E35-$D$35)),0) -> 24 | F41: =ROUND(($D$41*(1+$A$9)^(F35-$D$35)),0) -> 24 | G41: =ROUND(($D$41*(1+$A$9)^(G35-$D$35)),0) -> 24 | H41: =ROUND(($D$41*(1+$A$9)^(H35-$D$35)),0) -> 24 | I41: =ROUND(($D$41*(1+$A$9)^(I35-$D$35)),0) -> 24 | J41: =ROUND(($D$41*(1+$A$9)^(J35-$D$35)),0) -> 24 | K41: =ROUND(($D$41*(1+$A$9)^(K35-$D$35)),0) -> 24 | L41: =ROUND(($D$41*(1+$A$9)^(L35-$D$35)),0) -> 24 | ... P41: =ROUND(($D$41*(1+$A$9)^(P35-$D$35)),0) -> 24
C42: 4 años | D42: =+'POBLACION DEMANDANTE EFECTIVA'!D26*E30 -> 20.8 | E42: =ROUND(($D$42*(1+$A$9)^(E35-$D$35)),0) -> 21 | F42: =ROUND(($D$42*(1+$A$9)^(F35-$D$35)),0) -> 21 | G42: =ROUND(($D$42*(1+$A$9)^(G35-$D$35)),0) -> 21 | H42: =ROUND(($D$42*(1+$A$9)^(H35-$D$35)),0) -> 21 | I42: =ROUND(($D$42*(1+$A$9)^(I35-$D$35)),0) -> 21 | J42: =ROUND(($D$42*(1+$A$9)^(J35-$D$35)),0) -> 21 | K42: =ROUND(($D$42*(1+$A$9)^(K35-$D$35)),0) -> 21 | L42: =ROUND(($D$42*(1+$A$9)^(L35-$D$35)),0) -> 21 | ... P42: =ROUND(($D$42*(1+$A$9)^(P35-$D$35)),0) -> 21
C43: 5 a 11 años | D43: =+'POBLACION DEMANDANTE EFECTIVA'!D27*E31 -> 40.8 | E43: =ROUND(($D$43*(1+$A$9)^(E35-$D$35)),0) -> 41 | F43: =ROUND(($D$43*(1+$A$9)^(F35-$D$35)),0) -> 41 | G43: =ROUND(($D$43*(1+$A$9)^(G35-$D$35)),0) -> 41 | H43: =ROUND(($D$43*(1+$A$9)^(H35-$D$35)),0) -> 41 | I43: =ROUND(($D$43*(1+$A$9)^(I35-$D$35)),0) -> 41 | J43: =ROUND(($D$43*(1+$A$9)^(J35-$D$35)),0) -> 41 | K43: =ROUND(($D$43*(1+$A$9)^(K35-$D$35)),0) -> 41 | L43: =ROUND(($D$43*(1+$A$9)^(L35-$D$35)),0) -> 41 | ... P43: =ROUND(($D$43*(1+$A$9)^(P35-$D$35)),0) -> 41
C45: RATIO DE CONCENTRACION
C46: ATENCIONES PREVENTIVAS | D46: GRUPOS | E46: CONCENTRACION (DE ATENCION/PERSONA) CON PROYECTO
C47: ESTIMULACION TEMPRANA | D47: =+C57 -> < 29 dias | E47: 2
D48: =+C58 -> < 1 año | E48: 4
...

Sheet OFERTA ACTUAL 
B1: SERVICIOS PREVENTIVOS - CONTROL DE CRECIMIENTO Y DESARROLLO | E1: SERVICIOS PREVENTIVOS - CONTROL PRENATAL | H1: SERVICIOS PREVENTIVOS - CONSULTA EXTERNA (MEDICINA GENERAL)
B2: NRO. DE PERSONAL | C2: 1 | E2: NRO. DE PERSONAL | F2: 1 | H2: NRO. DE PERSONAL | I2: 1
B3: NUMERO HORAS ENFERMERO MENSUAL | C3: 150 HORAS (1.2 ES EL TIEMPO EFECTIVO | E3: NUMERO HORAS OBSTETRA MENSUAL | F3: 150 HORAS (1.2 ES EL TIEMPO EFECTIVO) | H3: NUMERO HORAS MEDICO MENSUAL | I3: 150 HORAS (0.7 h para consulta y 0.8 es de tiempo efectivo)
B4: NRO DE HORAS PROMEDIO DE ATENCION ANUAL DE CONSULTA EXTERNA (HORAS) | C4: =(150*11)*0.3 -> 495 | E4: NRO DE HORAS PROMEDIO DE ATENCION ANUAL DE CONSULTA EXTERNA (HORAS) | F4: =(150*12)*0.3 -> 540 | H4: NRO DE HORAS PROMEDIO DE ATENCION ANUAL DE CONSULTA EXTERNA (HORAS) | I4: =(150*12)*0.7 -> 1260
B5: NRO DE HORAS PROMEDIO DE ATENCION EFECTIVA ANUAL DE CONSULTA EXTERNA (3 HORAS DIARIAS) | C5: =C4*1.2 -> 594 | E5: NRO DE HORAS PROMEDIO DE ATENCION EFECTIVA ANUAL DE CONSULTA EXTERNA (3 HORAS DIARIAS) | F5: =F4*1.3 -> 702 | H5: NRO DE HORAS PROMEDIO DE ATENCION EFECTIVA ANUAL DE CONSULTA EXTERNA (4 HORAS DIARIAS) | I5: =I4*0.8 -> 1008
B6: ESTANDAR DE RENDIMIENTO HORA/PERSONAL | C6: 1 | E6: ESTANDAR DE RENDIMIENTO HORA/PERSONAL | F6: 2 | H6: ESTANDAR DE RENDIMIENTO HORA/PERSONAL | I6: 4
B8: OFERTA POR RECURSOS HUMANOS (NUMERO DE ATENCIONES/AÑO) | E8: OFERTA POR RECURSOS HUMANOS (NUMERO DE ATENCIONES/AÑO) | H8: OFERTA POR RECURSOS HUMANOS (NUMERO DE ATENCIONES/AÑO)
B9: OH= | C9: =C2*C5*C6 -> 594 | E9: OH= | F9: =F2*F5*F6 -> 1404 | H9: OH= | I9: =I2*I5*I6 -> 4032
B11: OFERTA POR RECURSO FISICO (NUMERO DE ATENCIONES/AÑO) | E11: OFERTA POR RECURSO FISICO (NUMERO DE ATENCIONES/AÑO) | H11: OFERTA POR RECURSO FISICO (NUMERO DE ATENCIONES/AÑO)
B12: OF= | C12: 0 | E12: OF= | F12: 0 | H12: OF= | I12: 0
B14: OFERTA OPTIMIZADA
B15: SERVICIOS | C15: POS INVERSION
C16: 1 | D16: 2 | E16: 3 | F16: 4 | G16: 5 | H16: 6 | I16: 7 | J16: 8 | K16: 9 | L16: 10
B17: =+'CART.SERVICIOS'!C4 -> Consultorio de medicina general | C17: 0 | D17: 0 | E17: 0 | F17: 0 | G17: 0 | H17: 0 | I17: 0 | J17: 0 | K17: 0 | L17: 0
B18: =+'CART.SERVICIOS'!C5 -> Teleconsultamedica | C18: 0 | D18: 0 | E18: 0 | F18: 0 | G18: 0 | H18: 0 | I18: 0 | J18: 0 | K18: 0 | L18: 0
B19: =+'CART.SERVICIOS'!C6 -> Consultorio CRED | C19: 0 | D19: 0 | E19: 0 | F19: 0 | G19: 0 | H19: 0 | I19: 0 | J19: 0 | K19: 0 | L19: 0
B20: =+'CART.SERVICIOS'!C7 -> Sala de estimulacion temprana | C20: 0 | D20: 0 | E20: 0 | F20: 0 | G20: 0 | H20: 0 | I20: 0 | J20: 0 | K20: 0 | L20: 0
B21: =+'CART.SERVICIOS'!C8 -> Sala de Inmunizaciones | C21: 0 | D21: 0 | E21: 0 | F21: 0 | G21: 0 | H21: 0 | I21: 0 | J21: 0 | K21: 0 | L21: 0
B22: =+'CART.SERVICIOS'!C9 -> Modulo para prevencion y consejeria de TBC | C22: 0 | D22: 0 | E22: 0 | F22: 0 | G22: 0 | H22: 0 | I22: 0 | J22: 0 | K22: 0 | L22: 0
B23: =+'CART.SERVICIOS'!C10 -> Consejeria y prevencion de ITS, VIH y SIDA | C23: 0 | D23: 0 | E23: 0 | F23: 0 | G23: 0 | H23: 0 | I23: 0 | J23: 0 | K23: 0 | L23: 0
B24: =+'CART.SERVICIOS'!C11 -> Atencíon integral y consejeria del Adolescente | C24: 0 | D24: 0 | E24: 0 | F24: 0 | G24: 0 | H24: 0 | I24: 0 | J24: 0 | K24: 0 | L24: 0
B25: =+'CART.SERVICIOS'!C12 -> Atencíon integral del Adulto Mayor | C25: 0 | D25: 0 | E25: 0 | F25: 0 | G25: 0 | H25: 0 | I25: 0 | J25: 0 | K25: 0 | L25: 0
B26: =+'CART.SERVICIOS'!C13 -> Consejería y prevención de Enf. No Transmisibles | C26: 0 | D26: 0 | E26: 0 | F26: 0 | G26: 0 | H26: 0 | I26: 0 | J26: 0 | K26: 0 | L26: 0
B27: =+'CART.SERVICIOS'!C14 -> Control Prenatal + 1/2 S.H. | C27: 0 | D27: 0 | E27: 0 | F27: 0 | G27: 0 | H27: 0 | I27: 0 | J27: 0 | K27: 0 | L27: 0
B28: =+'CART.SERVICIOS'!C15 -> Planificacíon Familiar | C28: 0 | D28: 0 | E28: 0 | F28: 0 | G28: 0 | H28: 0 | I28: 0 | J28: 0 | K28: 0 | L28: 0
... B37: =+'CART.SERVICIOS'!C24 -> Laboratorio | C37: 0 | D37: 0 | E37: 0 | F37: 0 | G37: 0 | H37: 0 | I37: 0 | J37: 0 | K37: 0 | L37: 0
B38: =+'CART.SERVICIOS'!C25 -> Ecografia | C38: 0 | D38: 0 | E38: 0 | F38: 0 | G38: 0 | H38: 0 | I38: 0 | J38: 0 | K38: 0 | L38: 0 | M38: 0
B39: =+'CART.SERVICIOS'!C26 -> Radiografia | C39: 0 | D39: 0 | E39: 0 | F39: 0 | G39: 0 | H39: 0 | I39: 0 | J39: 0 | K39: 0 | L39: 0

Sheet BALANCE OFERTA Y DEMANDA
A1: BLANCE OFERTA - DEMANDA
A2: SERVICIOS | B2: POST INVERSION
B3: 1 | C3: 2 | D3: 3 | E3: 4 | F3: 5 | G3: 6 | H3: 7 | I3: 8 | J3: 9 | K3: 10
A4: SERVICIOS PREVENTIVOS DE LA SALUD
A5: =+'DEMANDA SERV. DE SALUD CN PY'!C10 -> Medicina General
A6: Demanda efectiva con proyecto | B6: =+'DEMANDA SERV. DE SALUD CN PY'!G11 -> 512 | C6: =+'DEMANDA SERV. DE SALUD CN PY'!H11 -> 512 | D6: =+'DEMANDA SERV. DE SALUD CN PY'!I11 -> 512 | E6: =+'DEMANDA SERV. DE SALUD CN PY'!J11 -> 512 | F6: =+'DEMANDA SERV. DE SALUD CN PY'!K11 -> 512 | G6: =+'DEMANDA SERV. DE SALUD CN PY'!L11 -> 512 | H6: =+'DEMANDA SERV. DE SALUD CN PY'!M11 -> 512 | I6: =+'DEMANDA SERV. DE SALUD CN PY'!N11 -> 513 | ... K6: =+'DEMANDA SERV. DE SALUD CN PY'!P11 -> 513
A7: Oferta optimizada | B7: ='OFERTA ACTUAL '!C10 -> 0 | C7: ='OFERTA ACTUAL '!D10 -> 0 | D7: ='OFERTA ACTUAL '!E10 -> 0 | E7: ='OFERTA ACTUAL '!F10 -> 0 | F7: ='OFERTA ACTUAL '!G10 -> 0 | G7: ='OFERTA ACTUAL '!H10 -> 0 | H7: ='OFERTA ACTUAL '!I10 -> 0 | I7: ='OFERTA ACTUAL '!J10 -> 0 | ... K7: ='OFERTA ACTUAL '!L10 -> 0
A8: BRECHA (atenciones) | B8: =B7-B6 -> -512 | C8: =C7-C6 -> -512 | D8: =D7-D6 -> -512 | E8: =E7-E6 -> -512 | F8: =F7-F6 -> -512 | G8: =G7-G6 -> -512 | H8: =H7-H6 -> -512 | I8: =I7-I6 -> -513
A9: =+'DEMANDA SERV. DE SALUD CN PY'!C15 -> TELECONSULTA MEDICA
A10: Demanda efectiva con proyecto | B10: =+'DEMANDA SERV. DE SALUD CN PY'!E21 -> 341 | C10: =+'DEMANDA SERV. DE SALUD CN PY'!F21 -> 341 | D10: =+'DEMANDA SERV. DE SALUD CN PY'!G21 -> 341 | E10: =+'DEMANDA SERV. DE SALUD CN PY'!H21 -> 341 | F10: =+'DEMANDA SERV. DE SALUD CN PY'!I21 -> 341 | G10: =+'DEMANDA SERV. DE SALUD CN PY'!J21 -> 341 | H10: =+'DEMANDA SERV. DE SALUD CN PY'!K21 -> 341 | I10: =+'DEMANDA SERV. DE SALUD CN PY'!L21 -> 342 | ... K10: =+'DEMANDA SERV. DE SALUD CN PY'!N21 -> 342
A11: Oferta optimizada | B11: ='OFERTA ACTUAL '!C14 -> 0 | C11: ='OFERTA ACTUAL '!D14 -> 0 | D11: ='OFERTA ACTUAL '!E14 -> 0 | E11: ='OFERTA ACTUAL '!F14 -> 0 | F11: ='OFERTA ACTUAL '!G14 -> 0 | G11: ='OFERTA ACTUAL '!H14 -> 0 | H11: ='OFERTA ACTUAL '!I14 -> 0 | I11: ='OFERTA ACTUAL '!J14 -> 0 | ... K11: ='OFERTA ACTUAL '!L14 -> 0
A12: BRECHA (atenciones) | B12: =B11-B10 -> -341 | C12: =C11-C10 -> -341 | D12: =D11-D10 -> -341 | E12: =E11-E10 -> -341 | F12: =F11-F10 -> -341 | G12: =G11-G10 -> -341 | H12: =H11-H10 -> -341 | I12: =I11-I10 -> -342
A13: CONTROL DE CRECIMIENTO Y DESARROLLO
A14: Demanda efectiva con proyecto | B14: =+'DEMANDA SERV. DE SALUD CN PY'!G36 -> 162 | C14: =+'DEMANDA SERV. DE SALUD CN PY'!H36 -> 162 | D14: =+'DEMANDA SERV. DE SALUD CN PY'!I36 -> 162 | E14: =+'DEMANDA SERV. DE SALUD CN PY'!J36 -> 162 | F14: =+'DEMANDA SERV. DE SALUD CN PY'!K36 -> 162 | G14: =+'DEMANDA SERV. DE SALUD CN PY'!L36 -> 162 | H14: =+'DEMANDA SERV. DE SALUD CN PY'!M36 -> 162 | I14: =+'DEMANDA SERV. DE SALUD CN PY'!N36 -> 162 | ... K14: =+'DEMANDA SERV. DE SALUD CN PY'!P36 -> 162
A15: Oferta optimizada | B15: ='OFERTA ACTUAL '!C17 -> 0 | C15: ='OFERTA ACTUAL '!D17 -> 0 | D15: ='OFERTA ACTUAL '!E17 -> 0 | E15: ='OFERTA ACTUAL '!F17 -> 0 | F15: ='OFERTA ACTUAL '!G17 -> 0 | G15: ='OFERTA ACTUAL '!H17 -> 0 | H15: ='OFERTA ACTUAL '!I17 -> 0 | I15: ='OFERTA ACTUAL '!J17 -> 0 | ... K15: ='OFERTA ACTUAL '!L17 -> 0
A16: BRECHA (atenciones) | B16: =B15-B14 -> -162 | C16: =C15-C14 -> -162 | D16: =D15-D14 -> -162 | E16: =E15-E14 -> -162 | F16: =F15-F14 -> -162 | G16: =G15-G14 -> -162 | H16: =H15-H14 -> -162 | I16: =I15-I14 -> -162
